Workbook

Sheet 표지
M5: 내 역 서
A11: 공 사 명 : AI타워ㆍ지하주차장 신축공사 폐기물처리용역
A14: [ 건 설 폐 기 물 처 리 비 ]

Sheet 원가
B1: 공 사 원 가 계 산 서
B2: AI타워ㆍ지하주차장 신축공사 폐기물처리용역
B3: 비 목 | F3: 폐기물처리비 | H3: 구성비 | I3: 요율 | J3: 비고
C5: 순 공 사 비
A6: A1 | B6: 순 공 사 원 가 | C6: 재료비 | D6: 직접재료비
D7: [ 소 계 ]
A8: B2 | C8: 노무비 | D8: 직접노무비
D9: 간접노무비 | H9: 직접노무비 * 요율 | I9: 0.147
D10: [ 소 계 ]
C11: 경 비 | D11: 산출경비
A12: C2 | D12: 산업재해보상보험료 | H12: 노무비 * 요율 | I12: 0.0356
A13: C7 | D13: 고용보험료 | H13: 노무비 * 요율 | I13: 0.013
A14: C8 | D14: 국민건강보험료 | H14: 직접노무비 * 요율 | I14: 0.03595
A15: C9 | D15: 노인장기요양보험료 | H15: 국민건강보험료 * 요율 | I15: 0.1314
A16: CA | D16: 국민연금보험료 | H16: 직접노무비 * 요율 | I16: 0.0475
A17: C6 | D17: 퇴직공제부금비 | H17: 직접노무비 * 요율 | I17: 0.023
A18: C3 | D18: 산업안전보건관리비 | H18: 산출방법 (a),(b)중 작은값 | I18: 0.0237
E19: ⓐ 산정방법 | H19: (a) (재료비+직접노무비+(지급자재납품도/1.1))*요율
E20: ⓑ 산정방법 | H20: (b) ((재료비+직접노무비)*요율)*1.2
D21: 환경보전비 | H21: (재료비+직접노무비+산출경비) * 요율 | I21: 0.005
D22: 공사이행보증수수료 | H22: [4백만원+(직공비-500억)*0.004%]*공기(년) | I22: 4e-05
A23: CB | D23: 하도급대금지급보증서발급수수료 | H23: (재료비+직접노무비+산출경비) * 요율 | I23: 0.00068
D24: 건설기계대여대금 지급보증서발급수수료 | H24: (재료비+직접노무비+산출경비) * 요율 | I24: 0.0007
A25: C4 | D25: 기타경비 | H25: (재료비+노무비) * 요율 | I25: 0.057
A26: C4 | D26: 법정분담금 - 석면분담금 | H26: (재료비+노무비) * 요율 | I26: 6e-05
A27: C4 | D27: 법정분담금 - 임금채권부담금 | H27: (재료비+노무비) * 요율 | I27: 0.0009
D28: [ 소 계 ]
A29: S1 | B29: 순 공 사 원 가 | H29: 재료비+노무비+경비
A30: D1 | B30: 일 반 관 리 비 | H30: [재료비+노무비+경비] * 요율 | I30: 0.04 | K30: 단수정리
A31: D2 | B31: 이 윤 | H31: [노무비+경비+일반관리비] * 요율 | I31: 0.06
A32: D2
A33: E3 | B33: 제경비적용 제외 공종 (소계) | H33: 제비율적용제외공종 | I33: 0.00312
C34: 작업부산물
A37: S4 | B37: 총 원 가 | F37: =+ROUNDUP(공종별총괄표!L5+공종별총괄표!L10,-3) -> 0
A38: T2 | B38: 매 입 부 가 가 치 세 | H38: [직접재료비*매입세비율] * 요율 | M38: =+(133687.12-365.49)/133687.112 -> 0.99726614 | N38: 매입세율 비율
A39: T2 | B39: 부 가 가 치 세 | F39: =+ROUNDUP(F37*I39,-3) -> 0 | H39: [직접재료비*과세비율] * 요율 | I39: 0.1
A40: S7 | B40: 도 급 공 사 비
A41: U1 | B41: 건 설 폐 기 물 처 리 비 | F41: =F37+F39 -> 0
B42: 품 질 시 험 비
B43: 안 전 괸 리 비
...

Sheet 공종별총괄표
A1: 공 종 별 총 괄 집 계 표
A2: AI타워ㆍ지하주차장 신축공사 폐기물처리용역
A3: 품 명 | B3: 규 격 | C3: 단위 | D3: 수량 | E3: 재 료 비 | G3: 노 무 비 | I3: 경 비 | K3: 합 계 | M3: 비 고 | N3: 공종코드 | O3: 변수 | P3: 상위공종 | Q3: 공종구분 | R3: 공종레벨 | S3: 공종소계 | T3: 원가계산서 연결금액
E4: 단 가 | F4: 금 액 | G4: 단 가 | H4: 금 액 | I4: 단 가 | J4: 금 액 | K4: 단 가 | L4: 금 액
A5: AI 타워 | D5: 1 | E5: =+SUM(F6:F7) -> 0 | F5: =E5*D5 -> 0 | G5: =+SUM(H6:H7) -> 0 | H5: =G5*D5 -> 0 | I5: =+SUM(J6:J7) -> 0 | J5: =I5*D5 -> 0 | K5: =E5+G5+I5 -> 0 | L5: =ROUNDUP(F5+H5+J5,0) -> 0
A6: 01 건축공사 | D6: 1 | F6: =E6*D6 -> 0 | H6: =G6*D6 -> 0 | I6: =+ROUNDUP(+건축_공종별내역서_AI타워!L24,0) -> 0 | J6: =I6*D6 -> 0 | K6: =E6+G6+I6 -> 0 | L6: =F6+H6+J6 -> 0 | N6: 0101 | P6: 01 | R6: 2
A7: 02 토목공사 | D7: 1 | E7: =건축_공종별내역서_AI타워!F45 -> 0 | F7: =E7*D7 -> 0 | H7: =G7*D7 -> 0 | I7: =건축_공종별내역서_AI타워!J45 -> 0 | J7: =I7*D7 -> 0 | K7: =E7+G7+I7 -> 0 | L7: =F7+H7+J7 -> 0
A10: 신규주차장 | D10: 1 | E10: =+SUM(F11:F12) -> 0 | F10: =E10*D10 -> 0 | G10: =+SUM(H11:H30) -> 0 | H10: =G10*D10 -> 0 | I10: =+SUM(J11:J12) -> 0 | J10: =I10*D10 -> 0 | K10: =E10+G10+I10 -> 0 | L10: =ROUNDUP(F10+H10+J10,0) -> 0
A11: 01 건축공사 | D11: 1 | F11: =E11*D11 -> 0 | H11: =G11*D11 -> 0 | I11: =+ROUNDUP(+건축_공종별내역서_신규주차장!L24,0) -> 0 | J11: =I11*D11 -> 0 | K11: =E11+G11+I11 -> 0 | L11: =F11+H11+J11 -> 0
A12: 02 토목공사 | D12: 1 | E12: =건축_공종별내역서_신규주차장!F45 -> 0 | F12: =E12*D12 -> 0 | H12: =G12*D12 -> 0 | I12: =건축_공종별내역서_신규주차장!J45 -> 0 | J12: =I12*D12 -> 0 | K12: =E12+G12+I12 -> 0 | L12: =F12+H12+J12 -> 0
A24: 총 합계금액 | F24: =+F5+F10 -> 0 | H24: =+H5 -> 0 | J24: =+J5+J10 -> 0 | L24: =+L5+L10 -> 0

Sheet 건축_공종별내역서_AI타워
A1: [ AI타워ㆍ지하주차장 신축공사 폐기물처리용역_AI타워 ]
A2: 품 명 | B2: 규 격 | C2: 단위 | D2: 수량 | E2: 재 료 비 | G2: 노 무 비 | I2: 경 비 | K2: 합 계 | M2: 비 고 | N2: 품목코드 | O2: 변수 | P2: 설정 | Q2: 공종코드 | R2: 일위 | S2: 단산 | T2: 자재 | U2: 손료적용 | V2: 손료저장 | W2: 적용율 | X2: JUK1 | Y2: JUK2 | Z2: JUK3 | AA2: JUK4 | AB2: JUK5 | AC2: JUK6 | AD2: JUK7 | AE2: JUK8 | AF2: JUK9 | AG2: JUK10 | AH2: JUK11 | AI2: JUK12 | AJ2: JUK13 | AK2: JUK14 | AL2: JUK15 | AM2: JUK16 | AN2: JUK17 | AO2: JUK18 | AP2: JUK19 | AQ2: JUK20 | AR2: 자재구분 | AS2: 공종구분 | AT2: 공종레벨 | AU2: 공종+자재 | AV2: 고유번호
E3: 단 가 | F3: 금 액 | G3: 단 가 | H3: 금 액 | I3: 단 가 | J3: 금 액 | K3: 단 가 | L3: 금 액
A4: 010120 건설폐기물처리비 | Q4: 010120
A5: 폐콘크리트 | B5: 이물질이 없는 순수한 폐콘크리트 | C5: TON | D5: 1909.913 | F5: =TRUNC(E5*D5, 0) -> 0 | H5: =TRUNC(G5*D5, 0) -> 0 | J5: =TRUNC(I5*D5, 0) -> 0 | K5: =TRUNC(E5+G5+I5, 0) -> 0 | L5: =TRUNC(F5+H5+J5, 0) -> 0 | N5: 5C1F232F4C2102E633EEEE1ED72DA8F53B7FBB | Q5: 010120 | R5: F | S5: F | T5: T | X5: 1 | AU5: 0101205C1F232F4C2102E633EEEE1ED72DA8F53B7FBB | AV5: 1610
A6: 건설폐재류 | B6: 가연성이 제거된 재활용이 가능한 혼합물 | C6: TON | D6: 32.026 | F6: =TRUNC(E6*D6, 0) -> 0 | H6: =TRUNC(G6*D6, 0) -> 0 | J6: =TRUNC(I6*D6, 0) -> 0 | K6: =TRUNC(E6+G6+I6, 0) -> 0 | L6: =TRUNC(F6+H6+J6, 0) -> 0 | N6: 5C1F232F4C2102E633EEEE1ED72DA8F53B7FB9 | Q6: 010120 | R6: F | S6: F | T6: T | X6: 1 | AU6: 0101205C1F232F4C2102E633EEEE1ED72DA8F53B7FB9 | AV6: 1611
A7: 폐목재류 | C7: TON | D7: 49.931 | F7: =TRUNC(E7*D7, 0) -> 0 | H7: =TRUNC(G7*D7, 0) -> 0 | J7: =TRUNC(I7*D7, 0) -> 0 | K7: =TRUNC(E7+G7+I7, 0) -> 0 | L7: =TRUNC(F7+H7+J7, 0) -> 0 | N7: 5C1F232F4C2102E633EEEE1ED72DA8F53B7FB2 | Q7: 010120 | R7: F | S7: F | T7: T | X7: 1 | AU7: 0101205C1F232F4C2102E633EEEE1ED72DA8F53B7FB2 | AV7: 1612
A8: 혼합건설폐기물 | B8: 건설폐재류에 가연성 5% 이하 혼합 | C8: TON | D8: 40.225 | F8: =TRUNC(E8*D8, 0) -> 0 | H8: =TRUNC(G8*D8, 0) -> 0 | J8: =TRUNC(I8*D8, 0) -> 0 | K8: =TRUNC(E8+G8+I8, 0) -> 0 | L8: =TRUNC(F8+H8+J8, 0) -> 0 | N8: 5C1F232F4C2102E633EEEE1ED72DA8F53B780B | Q8: 010120 | R8: F | S8: F | T8: T | X8: 1 | AU8: 0101205C1F232F4C2102E633EEEE1ED72DA8F53B780B | AV8: 1613
A9: 혼합건설폐기물 | B9: 그 밖의 건설폐기물에 가연성 5% 이하 혼합 | C9: TON | D9: 630.674 | F9: =TRUNC(E9*D9, 0) -> 0 | H9: =TRUNC(G9*D9, 0) -> 0 | J9: =TRUNC(I9*D9, 0) -> 0 | K9: =TRUNC(E9+G9+I9, 0) -> 0 | L9: =TRUNC(F9+H9+J9, 0) -> 0 | N9: 5C1F232F4C2102E633EEEE1ED72DA8F53D2E3D | Q9: 010120 | R9: F | S9: F | T9: T | X9: 1 | AU9: 0101205C1F232F4C2102E633EEEE1ED72DA8F53D2E3D | AV9: 1614 | AW9: 3496.914
A10: 건설폐재류 운반비 | B10: 24톤 덤프트럭, 30km | C10: TON | D10: 1941.91 | F10: =TRUNC(E10*D10, 0) -> 0 | H10: =TRUNC(G10*D10, 0) -> 0 | J10: =TRUNC(I10*D10, 0) -> 0 | K10: =TRUNC(E10+G10+I10, 0) -> 0 | L10: =TRUNC(F10+H10+J10, 0) -> 0 | N10: 5C1F232F4C2102E633EEEE1ED72C8399CDAEC2 | Q10: 010120 | R10: F | S10: F | T10: T | X10: 1 | AU10: 0101205C1F232F4C2102E633EEEE1ED72C8399CDAEC2 | AV10: 1618 | AW10: =SUM(D5:D9) -> 2662.769
A11: 혼합건설폐기물 운반비 | B11: 24톤 암롤트럭, 30km | C11: TON | D11: =D8+D9 -> 670.899 | F11: =TRUNC(E11*D11, 0) -> 0 | H11: =TRUNC(G11*D11, 0) -> 0 | J11: =TRUNC(I11*D11, 0) -> 0 | K11: =TRUNC(E11+G11+I11, 0) -> 0 | L11: =TRUNC(F11+H11+J11, 0) -> 0 | N11: 5C1F232F4C2102E633EEEE1ED72C8399CDAB0E | Q11: 010120 | R11: F | S11: F | T11: T | X11: 1 | AU11: 0101205C1F232F4C2102E633EEEE1ED72C8399CDAB0E | AV11: 1619
A12: 폐목재류 운반비 | B12: 25톤 암롤트럭, 30km | C12: TON | D12: 49.931 | F12: =TRUNC(E12*D12, 0) -> 0 | H12: =TRUNC(G12*D12, 0) -> 0 | J12: =TRUNC(I12*D12, 0) -> 0 | K12: =TRUNC(E12+G12+I12, 0) -> 0 | L12: =TRUNC(F12+H12+J12, 0) -> 0 | N12: 5C1F232F4C2102E633EEEE1ED72C8399CDAB07 | Q12: 010120 | R12: F | S12: F | T12: T | X12: 1 | AU12: 0101205C1F232F4C2102E633EEEE1ED72C8399CDAB07 | AV12: 1620 | AX12: =AW9+AW10+AW26 -> 8899.683
N14: 5D4B238C447B028659F5B89A79AB001 | Q14: 010120 | R14: F | S14: F | T14: F | AU14: 0101205D4B238C447B028659F5B89A79AB001 | AV14: 1631 | AX14: 8899.683
Q15: 010120
Q16: 010120
Q17: 010120
Q18: 010120
Q19: 010120
Q20: 010120
Q21: 010120
Q22: 010120
Q23: 010120
A24: [ 합 계 ] | F24: =SUMIF(Q5:Q23,"010120",F5:F23) -> 0 | H24: =SUMIF(Q5:Q23,"010120",H5:H23) -> 0 | J24: =SUMIF(Q5:Q23,"010120",J5:J23) -> 0 | L24: =SUMIF(Q5:Q23,"010120",L5:L23) -> 0 | N24: TOTAL
A25: 010121 토목폐기물처리비 | Q25: 010120
A26: 폐콘크리트 | B26: 이물질이 없는 순수한 폐콘크리트 | C26: TON | D26: 2118 | F26: =TRUNC(E26*D26, 0) -> 0 | H26: =TRUNC(G26*D26, 0) -> 0 | J26: =TRUNC(I26*D26, 0) -> 0 | K26: =TRUNC(E26+G26+I26, 0) -> 0 | L26: =TRUNC(F26+H26+J26, 0) -> 0 | N26: 5C1F232F4C2102E633EEEE1ED72DA8F53B7FBB | Q26: 010120 | R26: F | S26: F | T26: T | X26: 1 | AU26: 0101205C1F232F4C2102E633EEEE1ED72DA8F53B7FBB | AV26: 1610 | AW26: =SUM(D26:D27) -> 2740
A27: 폐아스콘 | C27: TON | D27: 622 | F27: =TRUNC(E27*D27, 0) -> 0 | H27: =TRUNC(G27*D27, 0) -> 0 | J27: =TRUNC(I27*D27, 0) -> 0 | K27: =TRUNC(E27+G27+I27, 0) -> 0 | L27: =TRUNC(F27+H27+J27, 0) -> 0 | N27: 5C1F232F4C2102E633EEEE1ED72DA8F53B7FB9 | Q27: 010120 | R27: F | S27: F | T27: T | X27: 1 | AU27: 0101205C1F232F4C2102E633EEEE1ED72DA8F53B7FB9 | AV27: 1611
A28: 폐기물운반비(폐콘크리트,폐아스콘) | B28: 24톤 덤프트럭, 30km | C28: TON | D28: 2744 | F28: =TRUNC(E28*D28, 0) -> 0 | H28: =TRUNC(G28*D28, 0) -> 0 | J28: =TRUNC(I28*D28, 0) -> 0 | K28: =TRUNC(E28+G28+I28, 0) -> 0 | L28: =TRUNC(F28+H28+J28, 0) -> 0 | N28: 5C1F232F4C2102E633EEEE1ED72DA8F53B7FB2 | Q28: 010120 | R28: F | S28: F | T28: T | X28: 1 | AU28: 0101205C1F232F4C2102E633EEEE1ED72DA8F53B7FB2 | AV28: 1612
A29: 고재처리 | C29: TON | D29: 4 | F29: =TRUNC(E29*D29, 0) -> 0 | H29: =TRUNC(G29*D29, 0) -> 0 | J29: =TRUNC(I29*D29, 0) -> 0 | K29: =TRUNC(E29+G29+I29, 0) -> 0 | L29: =TRUNC(F29+H29+J29, 0) -> 0 | N29: 5C1F232F4C2102E633EEEE1ED72DA8F53B780B | Q29: 010120 | R29: F | S29: F | T29: T | X29: 1 | AU29: 0101205C1F232F4C2102E633EEEE1ED72DA8F53B780B | AV29: 1613
N30: 5C1F232F4C2102E633EEEE1ED72DA8F53D2E3D | Q30: 010120 | R30: F | S30: F | T30: T | X30: 1 | AU30: 0101205C1F232F4C2102E633EEEE1ED72DA8F53D2E3D | AV30: 1614
N31: 5C1F232F4C2102E633EEEE1ED72C8399CDAEC2 | Q31: 010120 | R31: F | S31: F | T31: T | X31: 1 | AU31: 0101205C1F232F4C2102E633EEEE1ED72C8399CDAEC2 | AV31: 1618
N32: 5C1F232F4C2102E633EEEE1ED72C8399CDAB0E | Q32: 010120 | R32: F | S32: F | T32: T | X32: 1 | AU32: 0101205C1F232F4C2102E633EEEE1ED72C8399CDAB0E | AV32: 1619
N33: 5C1F232F4C2102E633EEEE1ED72C8399CDAB07 | Q33: 010120 | R33: F | S33: F | T33: T | X33: 1 | AU33: 0101205C1F232F4C2102E633EEEE1ED72C8399CDAB07 | AV33: 1620
N35: 5D4B238C447B028659F5B89A79AB001 | Q35: 010120 | R35: F | S35: F | T35: F | AU35: 0101205D4B238C447B028659F5B89A79AB001 | AV35: 1631
Q36: 010120
Q37: 010120
Q38: 010120
Q39: 010120
Q40: 010120
Q41: 010120
Q42: 010120
...

Sheet 건축_공종별내역서_신규주차장
A1: [ AI타워ㆍ지하주차장 신축공사 폐기물처리용역_신규주차장 ]
A2: 품 명 | B2: 규 격 | C2: 단위 | D2: 수량 | E2: 재 료 비 | G2: 노 무 비 | I2: 경 비 | K2: 합 계 | M2: 비 고 | N2: 품목코드 | O2: 변수 | P2: 설정 | Q2: 공종코드 | R2: 일위 | S2: 단산 | T2: 자재 | U2: 손료적용 | V2: 손료저장 | W2: 적용율 | X2: JUK1 | Y2: JUK2 | Z2: JUK3 | AA2: JUK4 | AB2: JUK5 | AC2: JUK6 | AD2: JUK7 | AE2: JUK8 | AF2: JUK9 | AG2: JUK10 | AH2: JUK11 | AI2: JUK12 | AJ2: JUK13 | AK2: JUK14 | AL2: JUK15 | AM2: JUK16 | AN2: JUK17 | AO2: JUK18 | AP2: JUK19 | AQ2: JUK20 | AR2: 자재구분 | AS2: 공종구분 | AT2: 공종레벨 | AU2: 공종+자재 | AV2: 고유번호
E3: 단 가 | F3: 금 액 | G3: 단 가 | H3: 금 액 | I3: 단 가 | J3: 금 액 | K3: 단 가 | L3: 금 액
A4: 010120 건설폐기물처리비 | Q4: 010120
A5: 폐콘크리트 | B5: 이물질이 없는 순수한 폐콘크리트 | C5: TON | D5: 328.926 | F5: =TRUNC(E5*D5, 0) -> 0 | H5: =TRUNC(G5*D5, 0) -> 0 | J5: =TRUNC(I5*D5, 0) -> 0 | K5: =TRUNC(E5+G5+I5, 0) -> 0 | L5: =TRUNC(F5+H5+J5, 0) -> 0 | N5: 5E6984D4F19C0C00C837A61FE283C394B050DE | Q5: 010120 | R5: F | S5: F | T5: T | X5: 1 | AU5: 0101205E6984D4F19C0C00C837A61FE283C394B050DE | AV5: 1622
A6: 폐목재류 | C6: TON | D6: 9.488 | F6: =TRUNC(E6*D6, 0) -> 0 | H6: =TRUNC(G6*D6, 0) -> 0 | J6: =TRUNC(I6*D6, 0) -> 0 | K6: =TRUNC(E6+G6+I6, 0) -> 0 | L6: =TRUNC(F6+H6+J6, 0) -> 0 | N6: 5E6984D4F19C0C00C837A61FE283C394B050D7 | Q6: 010120 | R6: F | S6: F | T6: T | X6: 1 | AU6: 0101205E6984D4F19C0C00C837A61FE283C394B050D7 | AV6: 1623
A7: 혼합건설폐기물 | B7: 그 밖의 건설폐기물에 가연성 5% 이하 혼합 | C7: TON | D7: 82.5 | F7: =TRUNC(E7*D7, 0) -> 0 | H7: =TRUNC(G7*D7, 0) -> 0 | J7: =TRUNC(I7*D7, 0) -> 0 | K7: =TRUNC(E7+G7+I7, 0) -> 0 | L7: =TRUNC(F7+H7+J7, 0) -> 0 | N7: 5E6984D4F19C0C00C837A61FE283C394B6FBAF | Q7: 010120 | R7: F | S7: F | T7: T | X7: 1 | AU7: 0101205E6984D4F19C0C00C837A61FE283C394B6FBAF | AV7: 1624
A8: 건설폐재류 운반비 | B8: 24톤 덤프트럭, 40km | C8: TON | D8: 328.926 | F8: =TRUNC(E8*D8, 0) -> 0 | H8: =TRUNC(G8*D8, 0) -> 0 | J8: =TRUNC(I8*D8, 0) -> 0 | K8: =TRUNC(E8+G8+I8, 0) -> 0 | L8: =TRUNC(F8+H8+J8, 0) -> 0 | N8: 5E6984D4F19C0C00C837A61FE2823A56B3DEED | Q8: 010120 | R8: F | S8: F | T8: T | X8: 1 | AU8: 0101205E6984D4F19C0C00C837A61FE2823A56B3DEED | AV8: 1628
A9: 혼합건설폐기물 운반비 | B9: 24톤 암롤트럭, 40km | C9: TON | D9: 82.5 | F9: =TRUNC(E9*D9, 0) -> 0 | H9: =TRUNC(G9*D9, 0) -> 0 | J9: =TRUNC(I9*D9, 0) -> 0 | K9: =TRUNC(E9+G9+I9, 0) -> 0 | L9: =TRUNC(F9+H9+J9, 0) -> 0 | N9: 5E6984D4F19C0C00C837A61FE2823A56B3DB1A | Q9: 010120 | R9: F | S9: F | T9: T | X9: 1 | AU9: 0101205E6984D4F19C0C00C837A61FE2823A56B3DB1A | AV9: 1629 | AW9: =SUM(D5:D7) -> 420.914
A10: 폐목재류 운반비 | B10: 25톤 암롤트럭, 30km | C10: TON | D10: 9.488 | F10: =TRUNC(E10*D10, 0) -> 0 | H10: =TRUNC(G10*D10, 0) -> 0 | J10: =TRUNC(I10*D10, 0) -> 0 | K10: =TRUNC(E10+G10+I10, 0) -> 0 | L10: =TRUNC(F10+H10+J10, 0) -> 0 | N10: 5E6984D4F19C0C00C837A61FE2823A56B3DB11 | Q10: 010120 | R10: F | S10: F | T10: T | X10: 1 | AU10: 0101205E6984D4F19C0C00C837A61FE2823A56B3DB11 | AV10: 1630
N11: 5F330455B197E4F9605758BB6E8A001 | Q11: 010120 | R11: F | S11: F | T11: F | AU11: 0101205F330455B197E4F9605758BB6E8A001 | AV11: 1632
Q12: 010120
Q13: 010120
Q14: 010120
Q15: 010120
Q16: 010120
Q17: 010120
Q18: 010120
Q19: 010120
Q20: 010120
Q21: 010120
Q22: 010120
Q23: 010120
A24: [ 합 계 ] | F24: =SUMIF(Q5:Q23,"010120",F5:F23) -> 0 | H24: =SUMIF(Q5:Q23,"010120",H5:H23) -> 0 | J24: =SUMIF(Q5:Q23,"010120",J5:J23) -> 0 | L24: =SUMIF(Q5:Q23,"010120",L5:L23) -> 0 | N24: TOTAL
A25: 010121 토목폐기물처리비 | Q25: 010120
A26: 폐콘크리트 | B26: 이물질이 없는 순수한 폐콘크리트 | C26: TON | D26: 1851 | F26: =TRUNC(E26*D26, 0) -> 0 | H26: =TRUNC(G26*D26, 0) -> 0 | J26: =TRUNC(I26*D26, 0) -> 0 | K26: =TRUNC(E26+G26+I26, 0) -> 0 | L26: =TRUNC(F26+H26+J26, 0) -> 0 | N26: 5E6984D4F19C0C00C837A61FE283C394B050DE | Q26: 010120 | R26: F | S26: F | T26: T | X26: 1 | AU26: 0101205E6984D4F19C0C00C837A61FE283C394B050DE | AV26: 1622 | AW26: =SUM(D26:D27) -> 3076 | AY26: =AW9+AW26 -> 3496.914
A27: 폐아스콘 | C27: TON | D27: 1225 | F27: =TRUNC(E27*D27, 0) -> 0 | H27: =TRUNC(G27*D27, 0) -> 0 | J27: =TRUNC(I27*D27, 0) -> 0 | K27: =TRUNC(E27+G27+I27, 0) -> 0 | L27: =TRUNC(F27+H27+J27, 0) -> 0 | N27: 5E6984D4F19C0C00C837A61FE283C394B050D7 | Q27: 010120 | R27: F | S27: F | T27: T | X27: 1 | AU27: 0101205E6984D4F19C0C00C837A61FE283C394B050D7 | AV27: 1623
A28: 폐기물운반비(폐콘크리트,폐아스콘) | B28: 24톤 덤프트럭, 30km | C28: TON | D28: 624 | F28: =TRUNC(E28*D28, 0) -> 0 | H28: =TRUNC(G28*D28, 0) -> 0 | J28: =TRUNC(I28*D28, 0) -> 0 | K28: =TRUNC(E28+G28+I28, 0) -> 0 | L28: =TRUNC(F28+H28+J28, 0) -> 0 | N28: 5E6984D4F19C0C00C837A61FE283C394B6FBAF | Q28: 010120 | R28: F | S28: F | T28: T | X28: 1 | AU28: 0101205E6984D4F19C0C00C837A61FE283C394B6FBAF | AV28: 1624
A29: 고재처리 | C29: TON | D29: 2 | F29: =TRUNC(E29*D29, 0) -> 0 | H29: =TRUNC(G29*D29, 0) -> 0 | J29: =TRUNC(I29*D29, 0) -> 0 | K29: =TRUNC(E29+G29+I29, 0) -> 0 | L29: =TRUNC(F29+H29+J29, 0) -> 0 | N29: 5E6984D4F19C0C00C837A61FE2823A56B3DEED | Q29: 010120 | R29: F | S29: F | T29: T | X29: 1 | AU29: 0101205E6984D4F19C0C00C837A61FE2823A56B3DEED | AV29: 1628
N30: 5E6984D4F19C0C00C837A61FE2823A56B3DB1A | Q30: 010120 | R30: F | S30: F | T30: T | X30: 1 | AU30: 0101205E6984D4F19C0C00C837A61FE2823A56B3DB1A | AV30: 1629
N31: 5E6984D4F19C0C00C837A61FE2823A56B3DB11 | Q31: 010120 | R31: F | S31: F | T31: T | X31: 1 | AU31: 0101205E6984D4F19C0C00C837A61FE2823A56B3DB11 | AV31: 1630
N32: 5F330455B197E4F9605758BB6E8A001 | Q32: 010120 | R32: F | S32: F | T32: F | AU32: 0101205F330455B197E4F9605758BB6E8A001 | AV32: 1632
Q33: 010120
Q34: 010120
Q35: 010120
Q36: 010120
Q37: 010120
Q38: 010120
Q39: 010120
Q40: 010120
...
