Workbook
Name __JJ132: #REF!
Name __JJ132: #REF!
Name __JK132: #REF!
Name __JK132: #REF!
Name __JN132: #REF!
Name __JN132: #REF!
Name __p1: #REF!
Name __p1: #REF!
Name _95년_포상금_지급내역: #REF!
Name _95년_포상금_지급내역: #REF!
Name _JJ132: #REF!
Name _JJ132: #REF!
Name _JK132: #REF!
Name _JK132: #REF!
Name _JN132: #REF!
Name _JN132: #REF!
Name _p1: #REF!
Name _p1: #REF!
Name a: #REF!
Name a: #REF!
Name alf: #REF!
Name alf: #REF!
Name b: #REF!
Name b: #REF!
Name BOX형수로집계: #REF!
Name BOX형수로집계: #REF!
Name CV_1C: #REF!
Name CV_1C: #REF!
Name d: #REF!
Name d: #REF!
Name e: #REF!
Name e: #REF!
Name N: #REF!
Name N: #REF!
Name P: #REF!
Name P: #REF!
Name Print_Area_MI: #REF!
Name Print_Area_MI: #REF!
Name Q: #REF!
Name Q: #REF!
Name SIZE: #REF!
Name SIZE: #REF!
Name Title_Print: #REF!
Name Title_Print: #REF!
Name 강감찬: #REF!
Name 강감찬: #REF!
Name 경계점말뚝: #REF!
Name 경계점말뚝: #REF!
Name 계약단가: #REF!
Name 계약단가: #REF!
Name 고급: #REF!
Name 고급: #REF!
Name 공공시설: #REF!
Name 공공시설: #REF!
Name 공사비: #REF!
Name 공사비: #REF!
Name 공업용뇌관2: #REF!
Name 공업용뇌관2: #REF!
Name 교육: #REF!
Name 교육: #REF!

Sheet 공사원가
A1: 공 사 원 가 계 산 서 | M1: 2 | N1: 1 = 일반건설공사(갑) 2 = 특수 및 기타건설공사
A2: [ 공사명 ] | C2: =총괄표!D1 -> [ 폴리텍대학교 성남캠퍼스 피지컬 AI센터 구축공사(전기) ] | H2: 20
A3: 비 목 | D3: 금 액 | E3: 구 성 비 | G3: 비 고 | M3: 2026.04.13 공고분부터 적용
A4: 순 공 사 원 가 | B4: 재료비 | C4: 직 접 재 료 비 | J4: 1 | M4: 직재비율 | N4: 100
C5: 간 접 재 료 비
C6: 작업설,부산물(△)
C7: [ 소 계 ]
B8: 노무비 | C8: 직 접 노 무 비 | J8: 1 | M8: 직노비율 | N8: 100
C9: 간 접 노 무 비 | E9: =IF(N9=0,0,CONCATENATE("(직접노무비) * ",N9*100," %")) -> (직접노무비) * 17.5 % | J9: 1 | M9: 간접노무비 | N9: 0.175 | O9: ☜2018년_건축공사_원가계산_제비율_적용기준
C10: [ 소 계 ]
B11: 경 비 | C11: 전 력 비 | J11: 1
C12: 운 반 비 | J12: 1
C13: 기 계 경 비 | J13: 1
C14: 품 질 관 리 비 | J14: 1
C15: 가 설 비 | J15: 1
C16: 산 재 보 험 료 | E16: (노무비) * 3.56 % | J16: 1 | M16: 산재보험료 | N16: 0.0356 | O16: ☜모든 건설공사에 적용(노동부고시 제2017-75호), 산업재해보상보험법 시행령 | Q16: ←적용대상 : 모든 건설공사
C17: 고 용 보 험 료 | E17: (노무비) * 1.01 % | J17: 1 | M17: 고용보험료 | N17: 0.0101 | O17: ☜모든 건설공사에 적용(국토부 고시 제2018-462호), 고용보험범 시행령 | Q17: ←적용대상 : 모든 건설공사
C18: 건 강 보 험 료 | E18: 0 | M18: 건강보험료 | O18: ☜공사기간 1개월(30일)이상 모든 공사에 반영(국토교통부 고시 제2018-462호), 노인장기요양보험법 시행령 제4조 | Q18: ←적용대상 : 공사기간 1개월(30일)이상 모든 건설공사
C19: 연 금 보 험 료 | E19: 0 | M19: 연금보험료 | O19: ☜공사기간 1개월(30일)이상 모든 공사에 반영(국토교통부 고시 제2018-462호), 노인장기요양보험법 시행령 제4조 | Q19: ←적용대상 : 공사기간 1개월(30일)이상 모든 건설공사
C20: 노인장기보험료 | E20: 0 | M20: 노인보험료 | Q20: ←적용대상 : 공사기간 1개월(30일)이상 모든 건설공사
C21: 퇴직공제부금비 | E21: (직접노무비) * 2.3 % | M21: 퇴직공제비 | N21: 0.023 | O21: 재료비+직접노무비+도급자관급 | P21: ☜추정금액 3억원 이상 건설공사(국토교통부 고시 제2015-610호) | Q21: ←적용대상 : 추정금액(추정가격+부가세+관급액) 공공부문(1억원이상), 민간부문(50억원이상)
C22: 산업안전보건관리비 | E22: (재료비+직접노무비+관급액/1.1) * 3.11 % | G22: (a),(b)중 작은값 | M22: 안전관리비 | N22: 0.0311 | O22: 0.0293 | P22: 0.0293 | Q22: 0.0228 | R22: 4325000 | S22: 0.0159 | T22: 2450000 | U22: ←적용대상 : 총 공사금액(도급액+도급자관급액) 2천만원 이상 건설공사
C23: -도급자관급불포함(a) | E23: (재료비+직접노무비) * 3.11 % * 1.2 | G23: =IF(D24>0,"도급자관급 제외값*1.2",IF(D24<1,"도급자관급 없음",0)) -> 도급자관급 없음 | N23: 5억미만 | O23: 안전관리비 대상액1 | P23: ☜재료비(도급자관급액포함) + 직노 | Q23: 50억미만:일반건설 | S23: 50억미만:특수및기타
C24: -도급자관급포함(b) | E24: (재료비+직접노무비+관급액/1.1) * 3.11 % | G24: =IF(D24>0,"도급자관급 포함값",0) -> 0
C25: 기 타 경 비 | E25: (재료비+노무비) * 5 % | M25: 기타경비 | N25: 0.05 | O25: ☜2018년_건축공사_원가계산_제비율_적용기준
C26: 환 경 보 전 비 | E26: 0 | M26: 환경보존 | Q26: ←적용제외 : 전기,통신,소방
C27: 석 면 분 담 금 | E27: (노무비) * 0.006 % | M27: 석면분담 | N27: 6e-05
C28: 임금채권부담금 | E28: (노무비) * 0.09 % | M28: 임금채권 | N28: 0.0009
C29: [ 소 계 ]
A30: [ 계 ] | E30: 재료비+노무비+경비 | N30: 5억미만 | Q30: 30억미만
A31: 일 반 관 리 비 | E31: =CONCATENATE("(재료비+노무비+경비) * ",N31*100," %") -> (재료비+노무비+경비) * 8 % | J31: 1 | M31: 일반관리비 | N31: 0.08 | Q31: 0.055
A32: 폐 기 물 처 리 비
A33: 이 윤 | E33: =CONCATENATE("(노무비+경비+일반관리비) * ",N33*100," %") -> (노무비+경비+일반관리비) * 10 % | J33: 1 | M33: 이 윤 | N33: 0.1
A34: 고 재 처 리 비
A35: [ 공 급 가 액 ] | M35: 이윤절사 | N35: 978 | R35: ☜ 도급액의 "=백단위" 입력
A36: [ 손해배상보험료 ] | E36: (공급가액) * 0.26477 % | G36: 최소공제금액 20,000 | M36: 손해배상 | N36: 0.0026477 | R36: 초과일수
A37: 부 가 가 치 세 | J37: 1
A38: [ 도 급 액 ]
A39: [ 도급자관급액 ]
A40: [ 관급자관급액 ] | J40: 1
...

Sheet 총괄표
A1: 총줄수-> | B1: 107 | C1: 2.0 | D1: [ 폴리텍대학교 성남캠퍼스 피지컬 AI센터 구축공사(전기) ] | AA1: 연속견적가로형식
A2: 번호 | B2: 공종코드 | C2: … | D2: 공 종 명 | E2: 규격 | F2: 단위 | G2: 수량 | H2: 재료비 | J2: 노무비 | M2: 경비 | P2: 계 | Q2: 비고
H3: 단가 | I3: 금액 | J3: 수량 | K3: 단가 | L3: 금액 | M3: 단가 | N3: 금액 | O3: 단가
B4: 공종줄 | D4: [폴리텍대학교 성남캠퍼스 피지컬 AI센터 구축공사(전기)]
B5: 001 | D5: 1. 전기공사 | F5: 식 | G5: 1 | H5: =총괄표!I81 -> 0 | I5: =G5*H5 -> 0 | K5: =총괄표!L81 -> 0 | L5: =G5*K5 -> 0 | M5: =총괄표!N81 -> 0 | N5: =G5*M5 -> 0 | P5: =SUM(I5,L5,N5) -> 0
I6: =G6*H6 -> 0 | L6: =G6*K6 -> 0 | N6: =G6*M6 -> 0 | P6: =SUM(I6,L6,N6) -> 0
I7: =G7*H7 -> 0 | L7: =G7*K7 -> 0 | N7: =G7*M7 -> 0 | P7: =SUM(I7,L7,N7) -> 0
I8: =G8*H8 -> 0 | L8: =G8*K8 -> 0 | N8: =G8*M8 -> 0 | P8: =SUM(I8,L8,N8) -> 0
I9: =G9*H9 -> 0 | L9: =G9*K9 -> 0 | N9: =G9*M9 -> 0 | P9: =SUM(I9,L9,N9) -> 0
I10: =G10*H10 -> 0 | L10: =G10*K10 -> 0 | N10: =G10*M10 -> 0 | P10: =SUM(I10,L10,N10) -> 0
I11: =G11*H11 -> 0 | L11: =G11*K11 -> 0 | N11: =G11*M11 -> 0 | P11: =SUM(I11,L11,N11) -> 0
I12: =G12*H12 -> 0 | L12: =G12*K12 -> 0 | N12: =G12*M12 -> 0 | P12: =SUM(I12,L12,N12) -> 0
I13: =G13*H13 -> 0 | L13: =G13*K13 -> 0 | N13: =G13*M13 -> 0 | P13: =SUM(I13,L13,N13) -> 0
I14: =G14*H14 -> 0 | L14: =G14*K14 -> 0 | N14: =G14*M14 -> 0 | P14: =SUM(I14,L14,N14) -> 0
I15: =G15*H15 -> 0 | L15: =G15*K15 -> 0 | N15: =G15*M15 -> 0 | P15: =SUM(I15,L15,N15) -> 0
I16: =G16*H16 -> 0 | L16: =G16*K16 -> 0 | N16: =G16*M16 -> 0 | P16: =SUM(I16,L16,N16) -> 0
I17: =G17*H17 -> 0 | L17: =G17*K17 -> 0 | N17: =G17*M17 -> 0 | P17: =SUM(I17,L17,N17) -> 0
... I28: =G28*H28 -> 0 | L28: =G28*K28 -> 0 | N28: =G28*M28 -> 0 | P28: =SUM(I28,L28,N28) -> 0
C29: Total | D29: ( 합 계 ) | I29: =TRUNC(SUM(I4:I28)) -> 0 | L29: =TRUNC(SUM(L4:L28)) -> 0 | N29: =TRUNC(SUM(N4:N28)) -> 0 | P29: =TRUNC(SUM(P4:P28)) -> 0
B30: 공종줄 | D30: [폴리텍대학교 성남캠퍼스 본관동 리모델링 전기공사]
B31: 002 | D31: 2.도급자관급 | F31: 식 | G31: 1 | H31: =총괄표!I107 -> 0 | I31: =G31*H31 -> 0 | K31: =총괄표!L107 -> 0 | L31: =G31*K31 -> 0 | M31: =총괄표!N107 -> 0 | N31: =G31*M31 -> 0 | P31: =SUM(I31,L31,N31) -> 0
I32: =G32*H32 -> 0 | L32: =G32*K32 -> 0 | N32: =G32*M32 -> 0 | P32: =SUM(I32,L32,N32) -> 0
I33: =G33*H33 -> 0 | L33: =G33*K33 -> 0 | N33: =G33*M33 -> 0 | P33: =SUM(I33,L33,N33) -> 0
I34: =G34*H34 -> 0 | L34: =G34*K34 -> 0 | N34: =G34*M34 -> 0 | P34: =SUM(I34,L34,N34) -> 0
I35: =G35*H35 -> 0 | L35: =G35*K35 -> 0 | N35: =G35*M35 -> 0 | P35: =SUM(I35,L35,N35) -> 0
I36: =G36*H36 -> 0 | L36: =G36*K36 -> 0 | N36: =G36*M36 -> 0 | P36: =SUM(I36,L36,N36) -> 0
I37: =G37*H37 -> 0 | L37: =G37*K37 -> 0 | N37: =G37*M37 -> 0 | P37: =SUM(I37,L37,N37) -> 0
I38: =G38*H38 -> 0 | L38: =G38*K38 -> 0 | N38: =G38*M38 -> 0 | P38: =SUM(I38,L38,N38) -> 0
I39: =G39*H39 -> 0 | L39: =G39*K39 -> 0 | N39: =G39*M39 -> 0 | P39: =SUM(I39,L39,N39) -> 0
I40: =G40*H40 -> 0 | L40: =G40*K40 -> 0 | N40: =G40*M40 -> 0 | P40: =SUM(I40,L40,N40) -> 0
I41: =G41*H41 -> 0 | L41: =G41*K41 -> 0 | N41: =G41*M41 -> 0 | P41: =SUM(I41,L41,N41) -> 0
I42: =G42*H42 -> 0 | L42: =G42*K42 -> 0 | N42: =G42*M42 -> 0 | P42: =SUM(I42,L42,N42) -> 0
I43: =G43*H43 -> 0 | L43: =G43*K43 -> 0 | N43: =G43*M43 -> 0 | P43: =SUM(I43,L43,N43) -> 0
... I54: =G54*H54 -> 0 | L54: =G54*K54 -> 0 | N54: =G54*M54 -> 0 | P54: =SUM(I54,L54,N54) -> 0
C55: Total | D55: ( 합 계 ) | I55: =TRUNC(SUM(I30:I54)) -> 0 | L55: =TRUNC(SUM(L30:L54)) -> 0 | N55: =TRUNC(SUM(N30:N54)) -> 0 | P55: =TRUNC(SUM(P30:P54)) -> 0
B56: 공종줄 | D56: 1.전기공사
B57: 00101 | D57: 1-1. 전력간선설비공사 | F57: 식 | G57: 1 | H57: =내역서!I29 -> 0 | I57: =G57*H57 -> 0 | K57: =내역서!L29 -> 0 | L57: =G57*K57 -> 0 | M57: =내역서!N29 -> 0 | N57: =G57*M57 -> 0 | P57: =SUM(I57,L57,N57) -> 0
B58: 00102 | D58: 1-2. 전등설비공사 | F58: 식 | G58: 1 | H58: =내역서!I81 -> 0 | I58: =G58*H58 -> 0 | K58: =내역서!L81 -> 0 | L58: =G58*K58 -> 0 | M58: =내역서!N81 -> 0 | N58: =G58*M58 -> 0 | P58: =SUM(I58,L58,N58) -> 0
B59: 00103 | D59: 1-3. 전열설비공사 | F59: 식 | G59: 1 | H59: =내역서!I107 -> 0 | I59: =G59*H59 -> 0 | K59: =내역서!L107 -> 0 | L59: =G59*K59 -> 0 | M59: =내역서!N107 -> 0 | N59: =G59*M59 -> 0 | P59: =SUM(I59,L59,N59) -> 0
B60: 00104 | D60: 1-4. 냉난방설비공사 | F60: 식 | G60: 1 | H60: =내역서!I133 -> 0 | I60: =G60*H60 -> 0 | K60: =내역서!L133 -> 0 | L60: =G60*K60 -> 0 | M60: =내역서!N133 -> 0 | N60: =G60*M60 -> 0 | P60: =SUM(I60,L60,N60) -> 0
...

Sheet 내역서
A1: 총줄수-> | B1: 185 | C1: 2.0 | D1: [ 폴리텍대학교 성남캠퍼스 피지컬 AI센터 구축공사(전기) ] | W1: 노임 계산 정보 | AA1: 부속재 및 손료
A2: 번호 | B2: 공종코드 | C2: 코드 | D2: 명 칭 | E2: 규 격 | F2: 단위 | G2: 수량 | H2: 재료비 | J2: 노무비 | M2: 경비 | P2: 계 | Q2: 비고 | W2: 노임계 | X2: 전체(%) | Y2: 공종별(%) | Z2: 노임 소수 | AA2: CD배관재 | AB2: 일반배관재 | AC2: 소모재 | AD2: 자재계 | AE2: 노임계
H3: 단가 | I3: 금액 | J3: 수량 | K3: 단가 | L3: 금액 | M3: 단가 | N3: 금액 | O3: 단가 | AD3: =IF(#REF! =0, "1",#REF!) -> #REF! | AE3: =IF(#REF! =0, "1",#REF!) -> #REF!
B4: 공종줄 | D4: 1.전기공사::1-1.전력간선설비공사
A5: 59753017049 | B5: 00101 | C5: 3913170620174440 | D5: 1종금속제가요전선관 | E5: 커넥터, 70 mm 일반-비방수 | F5: 개 | G5: 2
A6: 56959100806 | B6: 00101 | C6: EAB110216000 | D6: 1종금속제가요전선관 | E6: 70 mm 고장력-비방수 | F6: m | G6: 30 | AC6: =G6*H6 -> 0
A7: 5975D857081 | B7: 00101 | C7: E59753857081 | D7: 풀박스 | E7: 200×200×200 | F7: 개 | G7: 1
A8: 5975D857141 | B8: 00101 | C8: E59753857141 | D8: 풀박스 | E8: 300×300×300 | F8: 개 | G8: 1
A9: 59754967501 | B9: 00101 | C9: 3913170520175118 | D9: 케이블트레이부속품 | E9: JOINT CONNEC.아연도100Hx2.3 | F9: 개 | G9: 13
A10: 59754967521 | B10: 00101 | C10: 3913170520175120 | D10: 케이블트레이부속품 | E10: SHANK BOLT & NUT, 아연도 | F10: 개 | G10: 130
A11: 59754967561 | B11: 00101 | C11: 3913170520175124 | D11: 케이블트레이부속품 | E11: BONDING JUMPER, 35㎟ | F11: 개 | G11: 13
A12: 5975E977021 | B12: 00101 | C12: E59754977021 | D12: 덕트형 케이블트레이 | E12: DUCT, W 300 x H 100 | F12: m | G12: 21
A13: E145A927206 | B13: 00101 | C13: EE1450927206 | D13: 접지용비닐절연전선(F-GV) | E13: 25㎟ | F13: m | G13: 116 | AC13: =G13*H13 -> 0
A14: 56959100811 | B14: 00101 | C14: EMM062983138 | D14: 0.6/1kv F-CV 1C×50㎟/4열동시 | E14: 0.6/1kv F-CV 1C×50㎟ | F14: m | G14: 464 | AC14: =G14*H14 -> 0
A15: 56959100813 | B15: 00101 | C15: EMM063385051 | D15: PNL.LP-실습실 | E15: 700*1500*180 | F15: 면 | G15: 1
AE16: =TRUNC(SUM(AE4:AE15)) -> 0
I24: =TRUNC(G24*H24) -> 0 | L24: =TRUNC(G24*K24) -> 0 | N24: =TRUNC(G24*M24) -> 0 | P24: =SUM(I24,L24,N24) -> 0
I25: =TRUNC(G25*H25) -> 0 | L25: =TRUNC(G25*K25) -> 0 | N25: =TRUNC(G25*M25) -> 0 | P25: =SUM(I25,L25,N25) -> 0
I26: =TRUNC(G26*H26) -> 0 | L26: =TRUNC(G26*K26) -> 0 | N26: =TRUNC(G26*M26) -> 0 | P26: =SUM(I26,L26,N26) -> 0
I27: =TRUNC(G27*H27) -> 0 | L27: =TRUNC(G27*K27) -> 0 | N27: =TRUNC(G27*M27) -> 0 | P27: =SUM(I27,L27,N27) -> 0
I28: =TRUNC(G28*H28) -> 0 | L28: =TRUNC(G28*K28) -> 0 | N28: =TRUNC(G28*M28) -> 0 | P28: =SUM(I28,L28,N28) -> 0
B29: 합계줄 | D29: ( 합 계 ) | I29: =TRUNC(SUM(I4:I28)) -> 0 | L29: =TRUNC(SUM(L4:L28)) -> 0 | N29: =TRUNC(SUM(N4:N28)) -> 0 | P29: =TRUNC(SUM(P4:P28)) -> 0
B30: 공종줄 | D30: 1.전기공사::1-2.전등설비공사
A31: 5975D097002 | B31: 00102 | C31: E59753097002 | D31: 합성수지제 가요전선관 | E31: CD-난연성 16㎜ | F31: m | G31: 3 | AA31: =G31*H31 -> 0 | AC31: =G31*H31 -> 0
A32: 5975D097003 | B32: 00102 | C32: E59753097003 | D32: 합성수지제 가요전선관 | E32: CD-난연성 22㎜ | F32: m | G32: 3 | AA32: =G32*H32 -> 0 | AC32: =G32*H32 -> 0
A33: 59753017043 | B33: 00102 | C33: 3913170620174434 | D33: 1종금속제가요전선관 | E33: 커넥터, 16 mm 일반-비방수 | F33: 개 | G33: 50
A34: 59753017044 | B34: 00102 | C34: 3913170620174435 | D34: 1종금속제가요전선관 | E34: 커넥터, 22 mm 일반-비방수 | F34: 개 | G34: 6
A35: 56959100803 | B35: 00102 | C35: EAB110213000 | D35: 1종금속제가요전선관 | E35: 16 mm 고장력-비방수 | F35: m | G35: 229 | AC35: =G35*H35 -> 0
A36: 56959100804 | B36: 00102 | C36: EAB110214000 | D36: 1종금속제가요전선관 | E36: 22 mm 고장력-비방수 | F36: m | G36: 9 | AC36: =G36*H36 -> 0
A37: 5975D767011 | B37: 00102 | C37: E59753767011 | D37: 아우트렛박스 | E37: 8각 54㎜ | F37: 개 | G37: 18
A38: 5975D777102 | B38: 00102 | C38: E59753777102 | D38: 스위치박스 | E38: 1 개용 54 mm | F38: 개 | G38: 7
A39: 56959100807 | B39: 00102 | C39: EAB110217000 | D39: 연결박스 | E39: 8각 54㎜ | F39: 개 | G39: 9
A40: 59753767211 | B40: 00102 | C40: 3912130820174711 | D40: 아우트렛박스 커버 | E40: 커버, 8각, 둥근구멍(오목) | F40: 개 | G40: 18
A41: 5975D857021 | B41: 00102 | C41: E59753857021 | D41: 풀박스 | E41: 100×100×100 | F41: 개 | G41: 5
A42: 5975A897011 | B42: 00102 | C42: E59750897011 | D42: 레이스웨이 | E42: BODY, 70 x 40 | F42: m | G42: 236
A43: 59750897041 | B43: 00102 | C43: 3913170910034923 | D43: 레이스웨이 | E43: COVER, 70 x 40 | F43: m | G43: 92
A44: 59750897071 | B44: 00102 | C44: 3913170910034926 | D44: 레이스웨이 | E44: JOINER, 70 x 40 | F44: 개 | G44: 144
A45: 59750897101 | B45: 00102 | C45: 3913170910034929 | D45: 레이스웨이 | E45: END CAP, 70 x 40 | F45: 개 | G45: 11
A46: 5975B477025 | B46: 00102 | C46: E59751477025 | D46: 전선덕트 | E46: 알루미늄 50x35 mm | F46: m | G46: 8
A47: 56959100808 | B47: 00102 | C47: EMM481669624 | D47: 450/750V 내열비닐절연전선 | E47: HFIX 1.78mm(2.5㎟) | F47: m | G47: 1211 | AC47: =G47*H47 -> 0
...

Sheet 합산자재
A1: 총줄수-> | B1: 81 | C1: [ 폴리텍대학교 성남캠퍼스 본관동 리모델링 전기공사 ] - 합산자재목록
A2: 번호 | B2: … | C2: 코드 | D2: 명 칭 | E2: 규 격 | F2: 단위 | G2: 수량 | H2: 재료비 | I2: 노무비 | J2: 경비 | K2: 지급비 | L2: 계 | M2: 비고
C4: 3913170620035660 | D4: 합성수지제 가요전선관 | E4: CD, 16㎜ | F4: m | G4: 247.5 | H4: =TRUNC(#REF!*#REF!) -> #REF! | L4: =SUM(H4,I4,J4) -> #REF!
C5: 3913170610035664 | D5: 합성수지제 가요전선관 | E5: CD-난연성 16㎜ | F5: m | G5: 107.8 | H5: =TRUNC(#REF!*#REF!) -> #REF! | L5: =SUM(H5,I5,J5) -> #REF!
C6: 3913170610035665 | D6: 합성수지제 가요전선관 | E6: CD-난연성 22㎜ | F6: m | G6: 3.3 | H6: =TRUNC(#REF!*#REF!) -> #REF! | L6: =SUM(H6,I6,J6) -> #REF!
C7: 3913170620174425 | D7: 1종금속제가요전선관 | E7: 36 mm 일반-방수 | F7: m | G7: 36.3 | H7: =TRUNC(#REF!*#REF!) -> #REF! | L7: =SUM(H7,I7,J7) -> #REF!
C8: 3913170620174434 | D8: 1종금속제가요전선관 | E8: 커넥터, 16 mm 일반-비방수 | F8: 개 | G8: 60 | H8: =TRUNC(#REF!*#REF!) -> #REF! | L8: =SUM(H8,I8,J8) -> #REF!
C9: 3913170620174435 | D9: 1종금속제가요전선관 | E9: 커넥터, 22 mm 일반-비방수 | F9: 개 | G9: 6 | H9: =TRUNC(#REF!*#REF!) -> #REF! | L9: =SUM(H9,I9,J9) -> #REF!
C10: 3913170620174437 | D10: 1종금속제가요전선관 | E10: 커넥터, 36 mm 일반-비방수 | F10: 개 | G10: 4 | H10: =TRUNC(#REF!*#REF!) -> #REF! | L10: =SUM(H10,I10,J10) -> #REF!
C11: 3913170620174440 | D11: 1종금속제가요전선관 | E11: 커넥터, 70 mm 일반-비방수 | F11: 개 | G11: 2 | H11: =TRUNC(#REF!*#REF!) -> #REF! | L11: =SUM(H11,I11,J11) -> #REF!
C12: 3913170620174449 | D12: 1종금속제가요전선관 | E12: 커넥터, 36 mm 일반-방수 | F12: 개 | G12: 6 | H12: =TRUNC(#REF!*#REF!) -> #REF! | L12: =SUM(H12,I12,J12) -> #REF!
C13: 3913170620174478 | D13: 1종금속제가요전선관 | E13: 16 mm 고장력-비방수 | F13: m | G13: 584.1 | H13: =TRUNC(#REF!*#REF!) -> #REF! | L13: =SUM(H13,I13,J13) -> #REF!
C14: 3913170620174479 | D14: 1종금속제가요전선관 | E14: 22 mm 고장력-비방수 | F14: m | G14: 9.9 | H14: =TRUNC(#REF!*#REF!) -> #REF! | L14: =SUM(H14,I14,J14) -> #REF!
C15: 3913170620174481 | D15: 1종금속제가요전선관 | E15: 36 mm 고장력-비방수 | F15: m | G15: 26.4 | H15: =TRUNC(#REF!*#REF!) -> #REF! | L15: =SUM(H15,I15,J15) -> #REF!
... C66: 391115ZZ701Z0003 | D66: 조명기구 C TYPE -@관급자재 | E66: T5간접조명/LED 18W/1200mm | F66: EA | G66: 8 | H66: =TRUNC(#REF!*#REF!) -> #REF! | L66: =SUM(H66,I66,J66) -> #REF!
C67: L001010101000075 | D67: 노 무 비 | E67: 내선전공 | F67: 인 | G67: 256.2102 | I67: =TRUNC(#REF!) -> #REF! | L67: =SUM(H67,I67,J67) -> #REF!
C68: L001010101000078 | D68: 노 무 비 | E68: 저압케이블전공 | F68: 인 | G68: 18.7792 | I68: =TRUNC(#REF!) -> #REF! | L68: =SUM(H68,I68,J68) -> #REF!
C69: L001010101000002 | D69: 노 무 비 | E69: 보통인부 | F69: 인 | G69: 0.24 | I69: =TRUNC(#REF!) -> #REF! | L69: =SUM(H69,I69,J69) -> #REF!
L70: =SUM(H70,I70,J70) -> 0
L71: =SUM(H71,I71,J71) -> 0
L72: =SUM(H72,I72,J72) -> 0
L73: =SUM(H73,I73,J73) -> 0
L74: =SUM(H74,I74,J74) -> 0
L75: =SUM(H75,I75,J75) -> 0
L76: =SUM(H76,I76,J76) -> 0
L77: =SUM(H77,I77,J77) -> 0
L78: =SUM(H78,I78,J78) -> 0
L79: =SUM(H79,I79,J79) -> 0
L80: =SUM(H80,I80,J80) -> 0
L81: =SUM(H81,I81,J81) -> 0

Sheet 사용설명
B1: ** 반드시 다음 사항을 숙지하신 다음 수정 작업을 하십시오 **
A2: 1. | B2: 속성이 숫자인 셀을 삭제할 때는 반드시 'Delete' 키를 사용하십시오.
B3: **주의:'Space Bar' 로 지웠을 때는 '#Value' Error가 발생됩니다.
A4: 2. | B4: 일위대가(을지)는 소수점 처리 때문에 셀 속성을 '일반'으로 하였습니다.(소수점 능동 처리)
B5: **참고: (수량*단가)의 결과는 소수 한자리, 금액을 취합한 소계는 1원 이하 절사입니다.
A6: 3. | B6: 내역서에서는 수량에만 셀 속성을 '일반'으로 하였습니다.(소수점 능동 처리)
A7: 4. | B7: 단가수정은 '단가조사서'시트 에서 하십시오.
B8: a)표지와 원가 -> 총괄표 -> 내역서 ->일위대가와 합산자재 ->단가조사서 를 참조하고
B9: 있으므로 단가조사서의 결정단가를 수정하면 전체 금액이 갱신됩니다.
B10: **주의: 금액란은 공식이 걸려있으므로 조심하여 수정하십시오.
B11: b)전체 자재를 일정 요율(%)로 변경할 때는 옵션시트의 자재 적용율을 조정하면 됩니다.
A12: 5. | B12: 노임 단가는 '단가조사서'시트에서 품셈은 '노임근거'시트에서 수정하십시오.
B13: a)전체 노임을 일정 요율(%)로 변경할 때는 '옵션시트'의 전체노임 적용율을 조정하면 됩니다.
B14: b)공종별로 노임을 수정하려면 '옵션시트'의 공종별 노임 적용율을 조정하면 됩니다.
B15: c)케이블 및 전선 자재 단가를 추가로 조정하려면 그룹별 자재 적용율을 조정하면 됩니다.
B16: 그룹은 견적 프로그램에서 엑셀파일이 만들어질때 지정됩니다.
A17: 6. | B17: 겉표지의 모든 정보는 표지를 참조하였습니다.(정보 수정은 표지에서만 하시면 됩니다.)
A18: 7. | B18: 필수 :본 프로그램의 총 금액을 확인한 후 사용하십시오.
A19: 8. | B19: 본 파일의 내용을 인쇄할 경우, 미리보기를 통하여 페이지 절선을 확인 후 인쇄하십시오.
A20: 9. | B20: 관급자재 Sheet가 해당이 없을 경우엔 삭제하십시오.
A21: 10. | B21: 페이지 절선이 맞지 않으면 다음을 참고하십시오.
B33: a. 해당시트의 셀 전체를 선택합니다.
B34: b. 행높이를 적절히 가감하면 페이지 절선을 맞출 수 있습니다.
