Workbook

Sheet 원가
A1: 원 가 계 산 서
A3: 공사명: | C3: 전남고등학교 AI팩토리(미래교실) 구축사업(전기) | E3: 공사기간: 1 개월 미만
A4: 비 목 | C4: 구 분 | D4: 금 액 | E4: 구 성 비
B5: 재 료 비 | C5: 직 접 재 료 비
C6: 간 접 재 료 비
C7: ( 소 계 )
A8: 순 | B8: 노 무 비 | C8: 직 접 노 무 비
C9: 간 접 노 무 비 | E9: (직접 노무비) * 17.5 %
C10: ( 소 계 )
C11: 산 재 보 험 료 | E11: (노무비) * 3.56 %
C12: 고 용 보 험 료 | E12: (노무비) * 1.01 %
A13: 공 | C13: 안 전 관 리 비 | E13: (재료+직노+관급재/1.1) * 3.11 %
B14: 경 | C14: 기 타 경 비 | E14: (재료+노무) * 4.831 %(수도광열비포함)
C15: 법 정 분 담 금 | E15: (노무비) * 0.096 %
A18: 사
B22: 비
A23: 비
C25: ( 소 계 )
B26: ( 순 공 사 비 계 )
A27: 일 반 관 리 비 | E27: (재료+노무+경비) * 8 %
A28: 이 윤 | E28: (노무+경비+일반관리비) * 15 %
A29: ( 총 원 가 )
A30: 공사손해보험료 | E30: 순계약금액 * 0.26477%
A31: 부 가 가 치 세
A36: ( 총 계 )

Sheet 총괄표
A1: 총줄수-> | B1: 55 | C1: 2.0 | D1: [ 전남고등학교 AI팩토리(미래교실) 구축사업(전 ] | AA1: 연속견적가로형식
A2: 번호 | B2: 공종코드 | C2: … | D2: 공 종 명 | E2: 규격 | F2: 단위 | G2: 수량 | H2: 재료비 | J2: 노무비 | M2: 경비 | P2: 계 | Q2: 비고
H3: 단가 | I3: 금액 | J3: 수량 | K3: 단가 | L3: 금액 | M3: 단가 | N3: 금액 | O3: 단가
B4: 공종줄 | D4: [전남고등학교 AI팩토리(미래교실) 구축사업(전]
B5: 001 | D5: 1.전기공사 | F5: 식 | G5: 1 | N5: =G5*M5 -> 0 | P5: =SUM(I5,L5,N5) -> 0
I6: =G6*H6 -> 0 | L6: =G6*K6 -> 0 | N6: =G6*M6 -> 0 | P6: =SUM(I6,L6,N6) -> 0
I7: =G7*H7 -> 0 | L7: =G7*K7 -> 0 | N7: =G7*M7 -> 0 | P7: =SUM(I7,L7,N7) -> 0
I8: =G8*H8 -> 0 | L8: =G8*K8 -> 0 | N8: =G8*M8 -> 0 | P8: =SUM(I8,L8,N8) -> 0
I9: =G9*H9 -> 0 | L9: =G9*K9 -> 0 | N9: =G9*M9 -> 0 | P9: =SUM(I9,L9,N9) -> 0
I10: =G10*H10 -> 0 | L10: =G10*K10 -> 0 | N10: =G10*M10 -> 0 | P10: =SUM(I10,L10,N10) -> 0
I11: =G11*H11 -> 0 | L11: =G11*K11 -> 0 | N11: =G11*M11 -> 0 | P11: =SUM(I11,L11,N11) -> 0
I12: =G12*H12 -> 0 | L12: =G12*K12 -> 0 | N12: =G12*M12 -> 0 | P12: =SUM(I12,L12,N12) -> 0
I13: =G13*H13 -> 0 | L13: =G13*K13 -> 0 | N13: =G13*M13 -> 0 | P13: =SUM(I13,L13,N13) -> 0
I14: =G14*H14 -> 0 | L14: =G14*K14 -> 0 | N14: =G14*M14 -> 0 | P14: =SUM(I14,L14,N14) -> 0
I15: =G15*H15 -> 0 | L15: =G15*K15 -> 0 | N15: =G15*M15 -> 0 | P15: =SUM(I15,L15,N15) -> 0
I16: =G16*H16 -> 0 | L16: =G16*K16 -> 0 | N16: =G16*M16 -> 0 | P16: =SUM(I16,L16,N16) -> 0
I17: =G17*H17 -> 0 | L17: =G17*K17 -> 0 | N17: =G17*M17 -> 0 | P17: =SUM(I17,L17,N17) -> 0
... I28: =G28*H28 -> 0 | L28: =G28*K28 -> 0 | N28: =G28*M28 -> 0 | P28: =SUM(I28,L28,N28) -> 0
C29: Total | D29: ( 합 계 ) | I29: =TRUNC(SUM(I4:I28)) -> 0 | L29: =TRUNC(SUM(L4:L28)) -> 0 | N29: =TRUNC(SUM(N4:N28)) -> 0 | P29: =TRUNC(SUM(P4:P28)) -> 0
B30: 공종줄 | D30: 1.전기공사
B31: 00101 | D31: 1-1.전열설비공사 | F31: 식 | G31: 1 | N31: =G31*M31 -> 0 | P31: =SUM(I31,L31,N31) -> 0
B32: 00102 | D32: 1-2.전등설비공사 | F32: 식 | G32: 1 | N32: =G32*M32 -> 0 | P32: =SUM(I32,L32,N32) -> 0
N34: =G34*M34 -> 0 | P34: =SUM(I34,L34,N34) -> 0
I35: =G35*H35 -> 0 | L35: =G35*K35 -> 0 | N35: =G35*M35 -> 0 | P35: =SUM(I35,L35,N35) -> 0
I36: =G36*H36 -> 0 | L36: =G36*K36 -> 0 | N36: =G36*M36 -> 0 | P36: =SUM(I36,L36,N36) -> 0
I37: =G37*H37 -> 0 | L37: =G37*K37 -> 0 | N37: =G37*M37 -> 0 | P37: =SUM(I37,L37,N37) -> 0
I38: =G38*H38 -> 0 | L38: =G38*K38 -> 0 | N38: =G38*M38 -> 0 | P38: =SUM(I38,L38,N38) -> 0
I39: =G39*H39 -> 0 | L39: =G39*K39 -> 0 | N39: =G39*M39 -> 0 | P39: =SUM(I39,L39,N39) -> 0
I40: =G40*H40 -> 0 | L40: =G40*K40 -> 0 | N40: =G40*M40 -> 0 | P40: =SUM(I40,L40,N40) -> 0
I41: =G41*H41 -> 0 | L41: =G41*K41 -> 0 | N41: =G41*M41 -> 0 | P41: =SUM(I41,L41,N41) -> 0
I42: =G42*H42 -> 0 | L42: =G42*K42 -> 0 | N42: =G42*M42 -> 0 | P42: =SUM(I42,L42,N42) -> 0
I43: =G43*H43 -> 0 | L43: =G43*K43 -> 0 | N43: =G43*M43 -> 0 | P43: =SUM(I43,L43,N43) -> 0
I44: =G44*H44 -> 0 | L44: =G44*K44 -> 0 | N44: =G44*M44 -> 0 | P44: =SUM(I44,L44,N44) -> 0
I45: =G45*H45 -> 0 | L45: =G45*K45 -> 0 | N45: =G45*M45 -> 0 | P45: =SUM(I45,L45,N45) -> 0
I46: =G46*H46 -> 0 | L46: =G46*K46 -> 0 | N46: =G46*M46 -> 0 | P46: =SUM(I46,L46,N46) -> 0
... I54: =G54*H54 -> 0 | L54: =G54*K54 -> 0 | N54: =G54*M54 -> 0 | P54: =SUM(I54,L54,N54) -> 0
B55: 001 | C55: Total | D55: ( 합 계 ) | I55: =TRUNC(SUM(I30:I54)) -> 0 | L55: =TRUNC(SUM(L30:L54)) -> 0 | N55: =TRUNC(SUM(N30:N54)) -> 0 | P55: =TRUNC(SUM(P30:P54)) -> 0

Sheet 내역서
A1: 총줄수-> | B1: 133 | C1: 2.0 | D1: [ 전남고등학교 AI팩토리(미래교실) 구축사업(전 ] | W1: 노임 계산 정보 | AA1: 부속재 및 손료
A2: 번호 | B2: 공종코드 | C2: 코드 | D2: 명 칭 | E2: 규 격 | F2: 단위 | G2: 수량 | H2: 재료비 | J2: 노무비 | M2: 경비 | P2: 계 | Q2: 비고 | W2: 노임계 | X2: 전체(%) | Y2: 공종별(%) | Z2: 노임 소수 | AA2: CD배관재 | AB2: 일반배관재 | AC2: 소모재 | AD2: 자재계 | AE2: 노임계
H3: 단가 | I3: 금액 | J3: 수량 | K3: 단가 | L3: 금액 | M3: 단가 | N3: 금액 | O3: 단가 | AD3: =IF([1]옵션!$C$11 =0, "1", [1]옵션!$C$11) -> 1000 | AE3: =IF([1]옵션!$C$12 =0, "1", [1]옵션!$C$12) -> 1000
B4: 공종줄 | D4: 1.전기공사::1-1.전열설비공사
A5: 59753097002 | B5: 00101 | C5: 3913170610035664 | D5: 합성수지제 가요전선관 | E5: CD-난연성 16㎜ | F5: m | G5: =[1]산출집계!H5 -> 73 | M5: =[1]합산자재!J4 -> 0 | N5: =TRUNC(G5*M5) -> 0 | P5: =SUM(I5,L5,N5) -> 0 | AA5: =G5*H5 -> 0 | AC5: =G5*H5 -> 0
A6: 59753097004 | B6: 00101 | C6: 3913170610035666 | D6: 합성수지제 가요전선관 | E6: CD-난연성 28㎜ | F6: m | G6: =[1]산출집계!H6 -> 18 | M6: =[1]합산자재!J6 -> 0 | N6: =TRUNC(G6*M6) -> 0 | P6: =SUM(I6,L6,N6) -> 0 | AA6: =G6*H6 -> 0 | AC6: =G6*H6 -> 0
A7: A0600000000 | B7: 00101 | C7: RENT000000000001 | D7: [ 배관 부속재 ] | E7: CD 전선관의 40 % | F7: 식 | G7: 1 | N7: =TRUNC(G7*M7) -> 0 | P7: =SUM(I7,L7,N7) -> 0 | AA7: =TRUNC(SUM(AA4:AA6)) -> 0
A8: 59753017003 | B8: 00101 | C8: 3913170620174410 | D8: 1종금속제가요전선관 | E8: 16 mm 일반-비방수 | F8: m | G8: =[1]산출집계!H7 -> 312 | M8: =[1]합산자재!J7 -> 0 | N8: =TRUNC(G8*M8) -> 0 | P8: =SUM(I8,L8,N8) -> 0 | AC8: =G8*H8 -> 0
A9: 59753017004 | B9: 00101 | C9: 3913170620174411 | D9: 1종금속제가요전선관 | E9: 22 mm 일반-비방수 | F9: m | G9: =[1]산출집계!H8 -> 29 | M9: =[1]합산자재!J8 -> 0 | N9: =TRUNC(G9*M9) -> 0 | P9: =SUM(I9,L9,N9) -> 0 | AC9: =G9*H9 -> 0
A10: 59753777111 | B10: 00101 | C10: 3912130610035781 | D10: 스위치박스 | E10: 2 개용 54 mm | F10: 개 | G10: =[1]산출집계!H9 -> 16 | M10: =[1]합산자재!J11 -> 0 | N10: =TRUNC(G10*M10) -> 0 | P10: =SUM(I10,L10,N10) -> 0
A11: 59753767281 | B11: 00101 | C11: 3912130820174718 | D11: 아우트렛박스 커버 | E11: 커버, 4각,2개용S/W (오목) | F11: 개 | G11: =[1]산출집계!H10 -> 16 | M11: =[1]합산자재!J13 -> 0 | N11: =TRUNC(G11*M11) -> 0 | P11: =SUM(I11,L11,N11) -> 0
A12: MM584315798 | B12: 00101 | C12: 3913170420175321 | D12: 덕트형 케이블트레이 | E12: DUCT, W 100 x H 100 | F12: m | G12: =[1]산출집계!H11 -> 3 | M12: =[1]합산자재!J14 -> 0 | N12: =TRUNC(G12*M12) -> 0 | P12: =SUM(I12,L12,N12) -> 0
A13: MM300040370 | B13: 00101 | C13: 3913171221650780 | D13: Al MOLD | E13: CATV 3호 | F13: m | G13: =[1]산출집계!H12 -> 14 | M13: =[1]합산자재!J15 -> 0 | N13: =TRUNC(G13*M13) -> 0 | P13: =SUM(I13,L13,N13) -> 0
A14: E1450667003 | B14: 00101 | C14: 2612162922076728 | D14: 450/750V 내열비닐절연전선 | E14: HFIX 2.25mm(4㎟) | F14: m | G14: =[1]산출집계!H13 -> 490 | M14: =[1]합산자재!J17 -> 0 | N14: =TRUNC(G14*M14) -> 0 | P14: =SUM(I14,L14,N14) -> 0 | AC14: =G14*H14 -> 0
A15: E1450927202 | B15: 00101 | C15: 2612152420683696 | D15: 접지용비닐절연전선(F-GV) | E15: 4㎟ | F15: m | G15: =[1]산출집계!H14 -> 29 | M15: =[1]합산자재!J18 -> 0 | N15: =TRUNC(G15*M15) -> 0 | P15: =SUM(I15,L15,N15) -> 0 | AC15: =G15*H15 -> 0
A16: MM481502538 | B16: 00101 | C16: 2612161321233111 | D16: 600V 비닐 캡타이어케이블 | E16: VCT, 3심 1.5 ㎟ | F16: m | G16: =[1]산출집계!H15 -> 145 | M16: =[1]합산자재!J19 -> 0 | N16: =TRUNC(G16*M16) -> 0 | P16: =SUM(I16,L16,N16) -> 0 | AC16: =G16*H16 -> 0
A17: E1450287522 | B17: 00101 | C17: 2612162920683903 | D17: 폴리에틸렌 난연케이블 | E17: 0.6/1kv F-CV 2C×4㎟ | F17: m | G17: =[1]산출집계!H16 -> 28 | M17: =[1]합산자재!J20 -> 0 | N17: =TRUNC(G17*M17) -> 0 | P17: =SUM(I17,L17,N17) -> 0 | AC17: =G17*H17 -> 0
A18: E1450287539 | B18: 00101 | C18: 2612162920683922 | D18: 폴리에틸렌 난연케이블 | E18: 0.6/1kv F-CV 3C×4㎟ | F18: m | G18: =[1]산출집계!H17 -> 88 | M18: =[1]합산자재!J21 -> 0 | N18: =TRUNC(G18*M18) -> 0 | P18: =SUM(I18,L18,N18) -> 0 | AC18: =G18*H18 -> 0
A19: 61452167502 | B19: 00101 | C19: 2612160921650753 | D19: UTP 케이블 | E19: Cat.6 0.5mm 4P | F19: m | G19: =[1]산출집계!H18 -> 4 | M19: =[1]합산자재!J22 -> 0 | N19: =TRUNC(G19*M19) -> 0 | P19: =SUM(I19,L19,N19) -> 0 | AC19: =G19*H19 -> 0
A20: 59350317206 | B20: 00101 | C20: 3912140620170850 | D20: 콘센트 | E20: 매입-접지형, 250V 2구 | F20: 개 | G20: =[1]산출집계!H19 -> 15 | M20: =[1]합산자재!J27 -> 0 | N20: =TRUNC(G20*M20) -> 0 | P20: =SUM(I20,L20,N20) -> 0
A21: 59350317207 | B21: 00101 | C21: 3912140621030227 | D21: 방우콘센트 | E21: 매입-접지형, 250V 1구 | F21: 개 | G21: =[1]산출집계!H20 -> 1 | M21: =[1]합산자재!J28 -> 0 | N21: =TRUNC(G21*M21) -> 0 | P21: =SUM(I21,L21,N21) -> 0
A22: MM317275398 | B22: 00101 | C22: 4619150520689684 | D22: 시각경보기 | F22: 개 | G22: =[1]산출집계!H21 -> 1 | M22: =[1]합산자재!J29 -> 0 | N22: =TRUNC(G22*M22) -> 0 | P22: =SUM(I22,L22,N22) -> 0 | Q22: 철거재사용
A23: MM064790193 | B23: 00101 | C23: 391115ZZ701Z0001 | D23: HDMI CABLE | F23: m | G23: =[1]산출집계!H22 -> 16 | M23: =[1]합산자재!J39 -> 0 | N23: =TRUNC(G23*M23) -> 0 | P23: =SUM(I23,L23,N23) -> 0 | AC23: =G23*H23 -> 0
A24: MM064790161 | B24: 00101 | C24: 391115ZZ701Z0008 | D24: TV 유닛 철거 | F24: EA | G24: =[1]산출집계!H23 -> 1 | M24: =[1]합산자재!J46 -> 0 | N24: =TRUNC(G24*M24) -> 0 | P24: =SUM(I24,L24,N24) -> 0 | Q24: 철거자재
A25: MM064790155 | B25: 00101 | C25: 391115ZZ701Z0010 | D25: 기존 분전반 속판 철거 | F25: 면 | G25: =[1]산출집계!H24 -> 1 | M25: =[1]합산자재!J48 -> 0 | N25: =TRUNC(G25*M25) -> 0 | P25: =SUM(I25,L25,N25) -> 0 | Q25: 철거자재
A26: MM064790116 | B26: 00101 | C26: 391115ZZ701Z0011 | D26: 노출배관 철거 | F26: m | G26: =[1]산출집계!H25 -> 11 | H26: =[1]합산자재!H49 -> 0 | J26: =[1]산출집계!J25 -> 11 | K26: =[1]합산자재!I49 -> 0 | L26: =TRUNC(G26*K26) -> 0 | M26: =[1]합산자재!J49 -> 0 | N26: =TRUNC(G26*M26) -> 0 | P26: =SUM(I26,L26,N26) -> 0 | Q26: 철거자재 | AC26: =G26*H26 -> 0
A27: MM064790152 | B27: 00101 | C27: 391115ZZ701Z0012 | D27: 무선 AP 재설치 | F27: EA | G27: =[1]산출집계!H26 -> 1 | I27: =TRUNC(G27*H27) -> 0 | J27: =[1]산출집계!J26 -> 1 | K27: =[1]합산자재!I50 -> 0 | L27: =TRUNC(G27*K27) -> 0 | M27: =[1]합산자재!J50 -> 0 | N27: =TRUNC(G27*M27) -> 0 | P27: =SUM(I27,L27,N27) -> 0 | Q27: 철거재사용
A28: MM064790182 | B28: 00101 | C28: 391115ZZ701Z0013 | D28: 배관용 홈파기 | F28: m | G28: =[1]산출집계!H27 -> 30 | H28: =[1]합산자재!H51 -> 0 | I28: =TRUNC(G28*H28) -> 0 | J28: =[1]산출집계!J27 -> 30 | K28: =[1]합산자재!I51 -> 0 | L28: =TRUNC(G28*K28) -> 0 | M28: =[1]합산자재!J51 -> 0 | N28: =TRUNC(G28*M28) -> 0 | P28: =SUM(I28,L28,N28) -> 0 | Q28: 노임적용 | AC28: =G28*H28 -> 0
A29: MM064790158 | B29: 00101 | C29: 391115ZZ701Z0014 | D29: 빔 프로젝트(스크린포함) 철거 | F29: SET | G29: =[1]산출집계!H28 -> 1 | I29: =TRUNC(G29*H29) -> 0 | J29: =[1]산출집계!J28 -> 1 | K29: =[1]합산자재!I52 -> 0 | L29: =TRUNC(G29*K29) -> 0 | M29: =[1]합산자재!J52 -> 0 | N29: =TRUNC(G29*M29) -> 0 | P29: =SUM(I29,L29,N29) -> 0 | Q29: 철거자재
A30: MM064790148 | B30: 00101 | C30: 391115ZZ701Z0015 | D30: 소방감지기 재설치 | F30: EA | G30: =[1]산출집계!H29 -> 3 | I30: =TRUNC(G30*H30) -> 0 | J30: =[1]산출집계!J29 -> 3 | K30: =[1]합산자재!I53 -> 0 | L30: =TRUNC(G30*K30) -> 0 | M30: =[1]합산자재!J53 -> 0 | N30: =TRUNC(G30*M30) -> 0 | P30: =SUM(I30,L30,N30) -> 0 | Q30: 철거재사용
A31: MM064790135 | B31: 00101 | C31: 391115ZZ701Z0016 | D31: 소화전 외함 교체 | E31: 외함은 건축 지급 | F31: 면 | G31: =[1]산출집계!H30 -> 1 | I31: =TRUNC(G31*H31) -> 0 | J31: =[1]산출집계!J30 -> 1 | K31: =[1]합산자재!I54 -> 0 | L31: =TRUNC(G31*K31) -> 0 | M31: =[1]합산자재!J54 -> 0 | N31: =TRUNC(G31*M31) -> 0 | P31: =SUM(I31,L31,N31) -> 0 | Q31: 지급자재
A32: MM064790142 | B32: 00101 | C32: 391115ZZ701Z0018 | D32: 스피커 재설치 천장형 | F32: EA | G32: =[1]산출집계!H31 -> 5 | I32: =TRUNC(G32*H32) -> 0 | J32: =[1]산출집계!J31 -> 5 | K32: =[1]합산자재!I56 -> 0 | L32: =TRUNC(G32*K32) -> 0 | M32: =[1]합산자재!J56 -> 0 | N32: =TRUNC(G32*M32) -> 0 | P32: =SUM(I32,L32,N32) -> 0 | Q32: 철거재사용
A33: MM064790149 | B33: 00101 | C33: 391115ZZ701Z0019 | D33: 스피커 재설치 컬럼형 | F33: EA | G33: =[1]산출집계!H32 -> 2 | I33: =TRUNC(G33*H33) -> 0 | J33: =[1]산출집계!J32 -> 2 | K33: =[1]합산자재!I57 -> 0 | L33: =TRUNC(G33*K33) -> 0 | M33: =[1]합산자재!J57 -> 0 | N33: =TRUNC(G33*M33) -> 0 | P33: =SUM(I33,L33,N33) -> 0 | Q33: 철거재사용
A34: MM064790139 | B34: 00101 | C34: 391115ZZ701Z0020 | D34: 스피커 철거 | E34: 컬럼형 | F34: EA | G34: =[1]산출집계!H33 -> 5 | N34: =TRUNC(G34*M34) -> 0 | P34: =SUM(I34,L34,N34) -> 0 | Q34: 철거자재
A35: MM064790123 | B35: 00101 | C35: 391115ZZ701Z0021 | D35: 시스템 박스 교체 | F35: EA | G35: =[1]산출집계!H34 -> 1 | N35: =TRUNC(G35*M35) -> 0 | P35: =SUM(I35,L35,N35) -> 0
A36: MM064790113 | B36: 00101 | C36: 391115ZZ701Z0023 | D36: 콘센트 교체 | E36: 흰색 | F36: EA | G36: =[1]산출집계!H35 -> 8 | N36: =TRUNC(G36*M36) -> 0 | P36: =SUM(I36,L36,N36) -> 0
A37: MM064790166 | B37: 00101 | C37: 391115ZZ701Z0024 | D37: 콘센트리프트 | E37: 1구콘센트 4EA, | F37: EA | G37: =[1]산출집계!H36 -> 9 | N37: =TRUNC(G37*M37) -> 0 | P37: =SUM(I37,L37,N37) -> 0
A38: MM064790170 | B38: 00101 | C38: 391115ZZ701Z0025 | D38: 콘센트리프트 리모컨 | F38: EA | G38: =[1]산출집계!H37 -> 1 | N38: =TRUNC(G38*M38) -> 0 | P38: =SUM(I38,L38,N38) -> 0
A39: MM064790168 | B39: 00101 | C39: 391115ZZ701Z0026 | D39: 콘센트리프트판넬 | F39: 면 | G39: =[1]산출집계!H42 -> 1 | N39: =TRUNC(G39*M39) -> 0 | P39: =SUM(I39,L39,N39) -> 0
A40: MM064790110 | B40: 00101 | C40: 391115ZZ701Z0027 | D40: 콘센트 철거 | F40: EA | G40: =[1]산출집계!H43 -> 9 | N40: =TRUNC(G40*M40) -> 0 | P40: =SUM(I40,L40,N40) -> 0 | Q40: 철거자재 | Z40: 노임계
...
