Workbook

Sheet 원가계산서
A1: 공 사 원 가 계 산 서
A2: 공사명 : 전남고 2026학년도 AI 융합형 교육실 구축
A3: 구 분 비 목 | D3: 구 성 비 | E3: 금 액 | F3: 비 고
A5: 순 공 사 원 가 | B5: 재료비 | C5: 직 접 재 료 비 | G5: A1 | H5: 0
C6: 소 계 | G6: A | H6: 0
B7: 노무비 | C7: 직 접 노 무 비 | G7: B1 | H7: 0
C8: 간 접 노 무 비 | D8: ="직.노*"&H8*100&"%" -> 직.노*17.5% | G8: B2 | H8: 0.175
C9: 소 계 | G9: B | H9: 0
B10: 경 비 | C10: 기 계 경 비 | G10: C4 | H10: 0
C11: 산 재 보 험 료 | D11: ="(노)*"&H11*100&"%" -> (노)*3.56% | G11: C10 | H11: 0.0356
C12: 고 용 보 험 료 | D12: ="(노)*"&H12*100&"%" -> (노)*1.01% | G12: C11 | H12: 0.0101
C13: 건 강 보 험 료 | G13: C12 | H13: 0
C14: 연 금 보 험 료 | G14: C13 | H14: 0
C15: 노인 장기 요양보험료 | G15: C14 | H15: 0
C16: 산업안전 보건 관리비 | D16: ="(재+직.노)*"&H16*100&"%" -> (재+직.노)*3.11% | G16: C16 | H16: 0.0311
C17: 퇴 직 공 제 부 금 비 | G17: C15 | H17: 0
C18: 기 타 경 비 | D18: ="(재+노)*"&H18*100&"%" -> (재+노)*4.831% | G18: C20 | H18: 0.04831
C19: 수 도 광 열 비 | G19: U3 | H19: 0
C20: 환 경 보 전 비 | G20: C25 | H20: 0
C21: 건설기계대여보증수수료 | G21: C32 | H21: 0
C22: 건설하도급보증수수료 | G22: C30 | H22: 0
C23: 석 면 분 담 금 | D23: ="노*"&H23*100&"%" -> 노*0.006% | G23: C21 | H23: 6e-05
C24: 임 금 채 권 부 담 금 | D24: ="노*"&H24*100&"%" -> 노*0.09% | G24: C22 | H24: 0.0009
C25: 소 계 | G25: C | H25: 0
B26: 계 | G26: X | H26: 0
A27: 일 반 관 리 비 | D27: ="(재+노+경)*"&H27*100&"%" -> (재+노+경)*8% | G27: D | H27: 0.08
A28: 이 윤 | D28: ="(노+경+일)*"&H28*100&"%" -> (노+경+일)*15% | G28: E | H28: 0.15
A29: 폐 기 물 처 리 비 | G29: L | H29: 0
A30: 작 업 부 산 물 | G30: L2 | H30: 0
A31: 총 원 가 | G31: F | H31: 0
A32: 부 가 가 치 세 | D32: ="(총원가)*"&H32*100&"%" -> (총원가)*10% | G32: H | H32: 0.1
A33: 도 급 금 액 | G33: Y | H33: 0
A34: 총 공 사 금 액 | H34: 0

Sheet 집계표(건축)
A1: 집 계 표
A2: 공사명 : 전남고 2026학년도 AI 융합형 교육실 구축
A3: 품 명 | C3: 단위 | D3: 수량 | E3: 재 료 비 | G3: 노 무 비 | I3: 경 비 | K3: 합 계 | M3: 비고
E4: 단 가 | F4: 금 액 | G4: 단 가 | H4: 금 액 | I4: 단 가 | J4: 금 액 | K4: 단 가 | L4: 금 액 | N4: 손료요율 | O4: 손료구분 | P4: 적용구분 | Q4: 합계구분 | R4: 기계경비 | S4: 운반비 | T4: 작업부산물 | U4: 관급 | V4: 외주비 | W4: 장비비 | X4: 폐기물처리비 | Y4: 가설비 | Z4: 잡비제외분 | AA4: 사급자재대 | AB4: 관급자재대 | AC4: 관급자관급 | AD4: 품질시험비 | AE4: 수도광열비 | AF4: 공기중석면농도측정비 | AG4: 사용자항목5 | AH4: 사용자항목6 | AI4: 사용자항목7 | AJ4: 관급자재대2 | AK4: 작업부산물 | AL4: 해체계획비및검토비 | AM4: 사용자항목11 | AN4: 사용자항목12 | AO4: 사용자항목13 | AP4: 사용자항목14 | AQ4: 사용자항목15 | AR4: 사용자항목16 | AS4: 사용자항목17 | AT4: 사용자항목18 | AU4: 사용자항목19 | AV4: 간접재료비 | AW4: 품목구분 | AX4: 조달코드 | AY4: 구분
A5: 1. 건축공사 | C5: 식 | D5: 1 | Q5: 1 | R5: =D5*R48 -> 0 | S5: =D5*S48 -> 0 | T5: =D5*T48 -> 0 | U5: =D5*U48 -> 0 | V5: =D5*V48 -> 0 | W5: =D5*W48 -> 0 | X5: =D5*X48 -> 0 | Y5: =D5*Y48 -> 0 | Z5: =D5*Z48 -> 0 | AA5: =D5*AA48 -> 0 | AB5: =D5*AB48 -> 0 | AC5: =D5*AC48 -> 0 | AD5: =D5*AD48 -> 0 | AE5: =D5*AE48 -> 0 | AF5: =D5*AF48 -> 0 | AG5: =D5*AG48 -> 0 | AH5: =D5*AH48 -> 0 | AI5: =D5*AI48 -> 0 | AJ5: =D5*AJ48 -> 0 | AK5: =D5*AK48 -> 0 | AL5: =D5*AL48 -> 0 | AM5: =D5*AM48 -> 0 | AN5: =D5*AN48 -> 0 | AO5: =D5*AO48 -> 0 | AP5: =D5*AP48 -> 0 | AQ5: =D5*AQ48 -> 0 | AR5: =D5*AR48 -> 0 | AS5: =D5*AS48 -> 0 | AT5: =D5*AT48 -> 0 | AU5: =D5*AU48 -> 0 | AV5: =D5*AV48 -> 0
A6: 2. 기계설비공사 | C6: 식 | D6: 1 | Q6: 1 | R6: =D6*'내역서(건축)'!R290 -> 0 | S6: =D6*'내역서(건축)'!S290 -> 0 | T6: =D6*'내역서(건축)'!T290 -> 0 | U6: =D6*'내역서(건축)'!U290 -> 0 | V6: =D6*'내역서(건축)'!V290 -> 0 | W6: =D6*'내역서(건축)'!W290 -> 0 | X6: =D6*'내역서(건축)'!X290 -> 0 | Y6: =D6*'내역서(건축)'!Y290 -> 0 | Z6: =D6*'내역서(건축)'!Z290 -> 0 | AA6: =D6*'내역서(건축)'!AA290 -> 0 | AB6: =D6*'내역서(건축)'!AB290 -> 0 | AC6: =D6*'내역서(건축)'!AC290 -> 0 | AD6: =D6*'내역서(건축)'!AD290 -> 0 | AE6: =D6*'내역서(건축)'!AE290 -> 0 | AF6: =D6*'내역서(건축)'!AF290 -> 0 | AG6: =D6*'내역서(건축)'!AG290 -> 0 | AH6: =D6*'내역서(건축)'!AH290 -> 0 | AI6: =D6*'내역서(건축)'!AI290 -> 0 | AJ6: =D6*'내역서(건축)'!AJ290 -> 0 | AK6: =D6*'내역서(건축)'!AK290 -> 0 | AL6: =D6*'내역서(건축)'!AL290 -> 0 | AM6: =D6*'내역서(건축)'!AM290 -> 0 | AN6: =D6*'내역서(건축)'!AN290 -> 0 | AO6: =D6*'내역서(건축)'!AO290 -> 0 | AP6: =D6*'내역서(건축)'!AP290 -> 0 | AQ6: =D6*'내역서(건축)'!AQ290 -> 0 | AR6: =D6*'내역서(건축)'!AR290 -> 0 | AS6: =D6*'내역서(건축)'!AS290 -> 0 | AT6: =D6*'내역서(건축)'!AT290 -> 0 | AU6: =D6*'내역서(건축)'!AU290 -> 0 | AV6: =D6*'내역서(건축)'!AV290 -> 0
A7: 3. 폐기물처리비 | C7: 식 | D7: 1 | R7: =D7*'내역서(건축)'!R312 -> 0 | S7: =D7*'내역서(건축)'!S312 -> 0 | T7: =D7*'내역서(건축)'!T312 -> 0 | U7: =D7*'내역서(건축)'!U312 -> 0 | V7: =D7*'내역서(건축)'!V312 -> 0 | W7: =D7*'내역서(건축)'!W312 -> 0 | X7: =D7*'내역서(건축)'!X312 -> 0 | Y7: =D7*'내역서(건축)'!Y312 -> 0 | Z7: =D7*'내역서(건축)'!Z312 -> 0 | AA7: =D7*'내역서(건축)'!AA312 -> 0 | AB7: =D7*'내역서(건축)'!AB312 -> 0 | AC7: =D7*'내역서(건축)'!AC312 -> 0 | AD7: =D7*'내역서(건축)'!AD312 -> 0 | AE7: =D7*'내역서(건축)'!AE312 -> 0 | AF7: =D7*'내역서(건축)'!AF312 -> 0 | AG7: =D7*'내역서(건축)'!AG312 -> 0 | AH7: =D7*'내역서(건축)'!AH312 -> 0 | AI7: =D7*'내역서(건축)'!AI312 -> 0 | AJ7: =D7*'내역서(건축)'!AJ312 -> 0 | AK7: =D7*'내역서(건축)'!AK312 -> 0 | AL7: =D7*'내역서(건축)'!AL312 -> 0 | AM7: =D7*'내역서(건축)'!AM312 -> 0 | AN7: =D7*'내역서(건축)'!AN312 -> 0 | AO7: =D7*'내역서(건축)'!AO312 -> 0 | AP7: =D7*'내역서(건축)'!AP312 -> 0 | AQ7: =D7*'내역서(건축)'!AQ312 -> 0 | AR7: =D7*'내역서(건축)'!AR312 -> 0 | AS7: =D7*'내역서(건축)'!AS312 -> 0 | AT7: =D7*'내역서(건축)'!AT312 -> 0 | AU7: =D7*'내역서(건축)'!AU312 -> 0 | AV7: =D7*'내역서(건축)'!AV312 -> 0
A8: 4. 작업부산물 | C8: 식 | D8: 1
A26: 합 계 | R26: =SUM(R5:R8) -> 0 | S26: =SUM(S5:S8) -> 0 | T26: =SUM(T5:T8) -> 0 | U26: =SUM(U5:U8) -> 0 | V26: =SUM(V5:V8) -> 0 | W26: =SUM(W5:W8) -> 0 | X26: =SUM(X5:X8) -> 0 | Y26: =SUM(Y5:Y8) -> 0 | ... AY26: =SUM(AY5:AY8) -> 0
A27: 1. 건축공사
A28: 1. 가설공사 | C28: 식 | D28: 1 | Q28: 1 | R28: =D28*'내역서(건축)'!R26 -> 0 | S28: =D28*'내역서(건축)'!S26 -> 0 | T28: =D28*'내역서(건축)'!T26 -> 0 | U28: =D28*'내역서(건축)'!U26 -> 0 | V28: =D28*'내역서(건축)'!V26 -> 0 | W28: =D28*'내역서(건축)'!W26 -> 0 | X28: =D28*'내역서(건축)'!X26 -> 0 | Y28: =D28*'내역서(건축)'!Y26 -> 0 | Z28: =D28*'내역서(건축)'!Z26 -> 0 | AA28: =D28*'내역서(건축)'!AA26 -> 0 | AB28: =D28*'내역서(건축)'!AB26 -> 0 | AC28: =D28*'내역서(건축)'!AC26 -> 0 | AD28: =D28*'내역서(건축)'!AD26 -> 0 | AE28: =D28*'내역서(건축)'!AE26 -> 0 | AF28: =D28*'내역서(건축)'!AF26 -> 0 | AG28: =D28*'내역서(건축)'!AG26 -> 0 | AH28: =D28*'내역서(건축)'!AH26 -> 0 | AI28: =D28*'내역서(건축)'!AI26 -> 0 | AJ28: =D28*'내역서(건축)'!AJ26 -> 0 | AK28: =D28*'내역서(건축)'!AK26 -> 0 | AL28: =D28*'내역서(건축)'!AL26 -> 0 | AM28: =D28*'내역서(건축)'!AM26 -> 0 | AN28: =D28*'내역서(건축)'!AN26 -> 0 | AO28: =D28*'내역서(건축)'!AO26 -> 0 | AP28: =D28*'내역서(건축)'!AP26 -> 0 | AQ28: =D28*'내역서(건축)'!AQ26 -> 0 | AR28: =D28*'내역서(건축)'!AR26 -> 0 | AS28: =D28*'내역서(건축)'!AS26 -> 0 | AT28: =D28*'내역서(건축)'!AT26 -> 0 | AU28: =D28*'내역서(건축)'!AU26 -> 0 | AV28: =D28*'내역서(건축)'!AV26 -> 0
A29: 2. 창호공사 | C29: 식 | D29: 1 | Q29: 1 | R29: =D29*'내역서(건축)'!R48 -> 0 | S29: =D29*'내역서(건축)'!S48 -> 0 | T29: =D29*'내역서(건축)'!T48 -> 0 | U29: =D29*'내역서(건축)'!U48 -> 0 | V29: =D29*'내역서(건축)'!V48 -> 0 | W29: =D29*'내역서(건축)'!W48 -> 0 | X29: =D29*'내역서(건축)'!X48 -> 0 | Y29: =D29*'내역서(건축)'!Y48 -> 0 | Z29: =D29*'내역서(건축)'!Z48 -> 0 | AA29: =D29*'내역서(건축)'!AA48 -> 0 | AB29: =D29*'내역서(건축)'!AB48 -> 0 | AC29: =D29*'내역서(건축)'!AC48 -> 0 | AD29: =D29*'내역서(건축)'!AD48 -> 0 | AE29: =D29*'내역서(건축)'!AE48 -> 0 | AF29: =D29*'내역서(건축)'!AF48 -> 0 | AG29: =D29*'내역서(건축)'!AG48 -> 0 | AH29: =D29*'내역서(건축)'!AH48 -> 0 | AI29: =D29*'내역서(건축)'!AI48 -> 0 | AJ29: =D29*'내역서(건축)'!AJ48 -> 0 | AK29: =D29*'내역서(건축)'!AK48 -> 0 | AL29: =D29*'내역서(건축)'!AL48 -> 0 | AM29: =D29*'내역서(건축)'!AM48 -> 0 | AN29: =D29*'내역서(건축)'!AN48 -> 0 | AO29: =D29*'내역서(건축)'!AO48 -> 0 | AP29: =D29*'내역서(건축)'!AP48 -> 0 | AQ29: =D29*'내역서(건축)'!AQ48 -> 0 | AR29: =D29*'내역서(건축)'!AR48 -> 0 | AS29: =D29*'내역서(건축)'!AS48 -> 0 | AT29: =D29*'내역서(건축)'!AT48 -> 0 | AU29: =D29*'내역서(건축)'!AU48 -> 0 | AV29: =D29*'내역서(건축)'!AV48 -> 0
A30: 3. 철거공사 | C30: 식 | D30: 1 | Q30: 1 | R30: =D30*'내역서(건축)'!R70 -> 0 | S30: =D30*'내역서(건축)'!S70 -> 0 | T30: =D30*'내역서(건축)'!T70 -> 0 | U30: =D30*'내역서(건축)'!U70 -> 0 | V30: =D30*'내역서(건축)'!V70 -> 0 | W30: =D30*'내역서(건축)'!W70 -> 0 | X30: =D30*'내역서(건축)'!X70 -> 0 | Y30: =D30*'내역서(건축)'!Y70 -> 0 | Z30: =D30*'내역서(건축)'!Z70 -> 0 | AA30: =D30*'내역서(건축)'!AA70 -> 0 | AB30: =D30*'내역서(건축)'!AB70 -> 0 | AC30: =D30*'내역서(건축)'!AC70 -> 0 | AD30: =D30*'내역서(건축)'!AD70 -> 0 | AE30: =D30*'내역서(건축)'!AE70 -> 0 | AF30: =D30*'내역서(건축)'!AF70 -> 0 | AG30: =D30*'내역서(건축)'!AG70 -> 0 | AH30: =D30*'내역서(건축)'!AH70 -> 0 | AI30: =D30*'내역서(건축)'!AI70 -> 0 | AJ30: =D30*'내역서(건축)'!AJ70 -> 0 | AK30: =D30*'내역서(건축)'!AK70 -> 0 | AL30: =D30*'내역서(건축)'!AL70 -> 0 | AM30: =D30*'내역서(건축)'!AM70 -> 0 | AN30: =D30*'내역서(건축)'!AN70 -> 0 | AO30: =D30*'내역서(건축)'!AO70 -> 0 | AP30: =D30*'내역서(건축)'!AP70 -> 0 | AQ30: =D30*'내역서(건축)'!AQ70 -> 0 | AR30: =D30*'내역서(건축)'!AR70 -> 0 | AS30: =D30*'내역서(건축)'!AS70 -> 0 | AT30: =D30*'내역서(건축)'!AT70 -> 0 | AU30: =D30*'내역서(건축)'!AU70 -> 0 | AV30: =D30*'내역서(건축)'!AV70 -> 0
A31: 4. 칸막이공사 | C31: 식 | D31: 1 | Q31: 1 | R31: =D31*'내역서(건축)'!R92 -> 0 | S31: =D31*'내역서(건축)'!S92 -> 0 | T31: =D31*'내역서(건축)'!T92 -> 0 | U31: =D31*'내역서(건축)'!U92 -> 0 | V31: =D31*'내역서(건축)'!V92 -> 0 | W31: =D31*'내역서(건축)'!W92 -> 0 | X31: =D31*'내역서(건축)'!X92 -> 0 | Y31: =D31*'내역서(건축)'!Y92 -> 0 | Z31: =D31*'내역서(건축)'!Z92 -> 0 | AA31: =D31*'내역서(건축)'!AA92 -> 0 | AB31: =D31*'내역서(건축)'!AB92 -> 0 | AC31: =D31*'내역서(건축)'!AC92 -> 0 | AD31: =D31*'내역서(건축)'!AD92 -> 0 | AE31: =D31*'내역서(건축)'!AE92 -> 0 | AF31: =D31*'내역서(건축)'!AF92 -> 0 | AG31: =D31*'내역서(건축)'!AG92 -> 0 | AH31: =D31*'내역서(건축)'!AH92 -> 0 | AI31: =D31*'내역서(건축)'!AI92 -> 0 | AJ31: =D31*'내역서(건축)'!AJ92 -> 0 | AK31: =D31*'내역서(건축)'!AK92 -> 0 | AL31: =D31*'내역서(건축)'!AL92 -> 0 | AM31: =D31*'내역서(건축)'!AM92 -> 0 | AN31: =D31*'내역서(건축)'!AN92 -> 0 | AO31: =D31*'내역서(건축)'!AO92 -> 0 | AP31: =D31*'내역서(건축)'!AP92 -> 0 | AQ31: =D31*'내역서(건축)'!AQ92 -> 0 | AR31: =D31*'내역서(건축)'!AR92 -> 0 | AS31: =D31*'내역서(건축)'!AS92 -> 0 | AT31: =D31*'내역서(건축)'!AT92 -> 0 | AU31: =D31*'내역서(건축)'!AU92 -> 0 | AV31: =D31*'내역서(건축)'!AV92 -> 0
A32: 5. 복도 | C32: 식 | D32: 1 | Q32: 1 | R32: =D32*'내역서(건축)'!R114 -> 0 | S32: =D32*'내역서(건축)'!S114 -> 0 | T32: =D32*'내역서(건축)'!T114 -> 0 | U32: =D32*'내역서(건축)'!U114 -> 0 | V32: =D32*'내역서(건축)'!V114 -> 0 | W32: =D32*'내역서(건축)'!W114 -> 0 | X32: =D32*'내역서(건축)'!X114 -> 0 | Y32: =D32*'내역서(건축)'!Y114 -> 0 | Z32: =D32*'내역서(건축)'!Z114 -> 0 | AA32: =D32*'내역서(건축)'!AA114 -> 0 | AB32: =D32*'내역서(건축)'!AB114 -> 0 | AC32: =D32*'내역서(건축)'!AC114 -> 0 | AD32: =D32*'내역서(건축)'!AD114 -> 0 | AE32: =D32*'내역서(건축)'!AE114 -> 0 | AF32: =D32*'내역서(건축)'!AF114 -> 0 | AG32: =D32*'내역서(건축)'!AG114 -> 0 | AH32: =D32*'내역서(건축)'!AH114 -> 0 | AI32: =D32*'내역서(건축)'!AI114 -> 0 | AJ32: =D32*'내역서(건축)'!AJ114 -> 0 | AK32: =D32*'내역서(건축)'!AK114 -> 0 | AL32: =D32*'내역서(건축)'!AL114 -> 0 | AM32: =D32*'내역서(건축)'!AM114 -> 0 | AN32: =D32*'내역서(건축)'!AN114 -> 0 | AO32: =D32*'내역서(건축)'!AO114 -> 0 | AP32: =D32*'내역서(건축)'!AP114 -> 0 | AQ32: =D32*'내역서(건축)'!AQ114 -> 0 | AR32: =D32*'내역서(건축)'!AR114 -> 0 | AS32: =D32*'내역서(건축)'!AS114 -> 0 | AT32: =D32*'내역서(건축)'!AT114 -> 0 | AU32: =D32*'내역서(건축)'!AU114 -> 0 | AV32: =D32*'내역서(건축)'!AV114 -> 0
A33: 6. 기술실 | C33: 식 | D33: 1 | Q33: 1 | R33: =D33*'내역서(건축)'!R158 -> 0 | S33: =D33*'내역서(건축)'!S158 -> 0 | T33: =D33*'내역서(건축)'!T158 -> 0 | U33: =D33*'내역서(건축)'!U158 -> 0 | V33: =D33*'내역서(건축)'!V158 -> 0 | W33: =D33*'내역서(건축)'!W158 -> 0 | X33: =D33*'내역서(건축)'!X158 -> 0 | Y33: =D33*'내역서(건축)'!Y158 -> 0 | Z33: =D33*'내역서(건축)'!Z158 -> 0 | AA33: =D33*'내역서(건축)'!AA158 -> 0 | AB33: =D33*'내역서(건축)'!AB158 -> 0 | AC33: =D33*'내역서(건축)'!AC158 -> 0 | AD33: =D33*'내역서(건축)'!AD158 -> 0 | AE33: =D33*'내역서(건축)'!AE158 -> 0 | AF33: =D33*'내역서(건축)'!AF158 -> 0 | AG33: =D33*'내역서(건축)'!AG158 -> 0 | AH33: =D33*'내역서(건축)'!AH158 -> 0 | AI33: =D33*'내역서(건축)'!AI158 -> 0 | AJ33: =D33*'내역서(건축)'!AJ158 -> 0 | AK33: =D33*'내역서(건축)'!AK158 -> 0 | AL33: =D33*'내역서(건축)'!AL158 -> 0 | AM33: =D33*'내역서(건축)'!AM158 -> 0 | AN33: =D33*'내역서(건축)'!AN158 -> 0 | AO33: =D33*'내역서(건축)'!AO158 -> 0 | AP33: =D33*'내역서(건축)'!AP158 -> 0 | AQ33: =D33*'내역서(건축)'!AQ158 -> 0 | AR33: =D33*'내역서(건축)'!AR158 -> 0 | AS33: =D33*'내역서(건축)'!AS158 -> 0 | AT33: =D33*'내역서(건축)'!AT158 -> 0 | AU33: =D33*'내역서(건축)'!AU158 -> 0 | AV33: =D33*'내역서(건축)'!AV158 -> 0
A34: 7. 장비실 | C34: 식 | D34: 1 | Q34: 1 | R34: =D34*'내역서(건축)'!R180 -> 0 | S34: =D34*'내역서(건축)'!S180 -> 0 | T34: =D34*'내역서(건축)'!T180 -> 0 | U34: =D34*'내역서(건축)'!U180 -> 0 | V34: =D34*'내역서(건축)'!V180 -> 0 | W34: =D34*'내역서(건축)'!W180 -> 0 | X34: =D34*'내역서(건축)'!X180 -> 0 | Y34: =D34*'내역서(건축)'!Y180 -> 0 | Z34: =D34*'내역서(건축)'!Z180 -> 0 | AA34: =D34*'내역서(건축)'!AA180 -> 0 | AB34: =D34*'내역서(건축)'!AB180 -> 0 | AC34: =D34*'내역서(건축)'!AC180 -> 0 | AD34: =D34*'내역서(건축)'!AD180 -> 0 | AE34: =D34*'내역서(건축)'!AE180 -> 0 | AF34: =D34*'내역서(건축)'!AF180 -> 0 | AG34: =D34*'내역서(건축)'!AG180 -> 0 | AH34: =D34*'내역서(건축)'!AH180 -> 0 | AI34: =D34*'내역서(건축)'!AI180 -> 0 | AJ34: =D34*'내역서(건축)'!AJ180 -> 0 | AK34: =D34*'내역서(건축)'!AK180 -> 0 | AL34: =D34*'내역서(건축)'!AL180 -> 0 | AM34: =D34*'내역서(건축)'!AM180 -> 0 | AN34: =D34*'내역서(건축)'!AN180 -> 0 | AO34: =D34*'내역서(건축)'!AO180 -> 0 | AP34: =D34*'내역서(건축)'!AP180 -> 0 | AQ34: =D34*'내역서(건축)'!AQ180 -> 0 | AR34: =D34*'내역서(건축)'!AR180 -> 0 | AS34: =D34*'내역서(건축)'!AS180 -> 0 | AT34: =D34*'내역서(건축)'!AT180 -> 0 | AU34: =D34*'내역서(건축)'!AU180 -> 0 | AV34: =D34*'내역서(건축)'!AV180 -> 0
A35: 8. 가구공사 | C35: 식 | D35: 1 | Q35: 1 | R35: =D35*'내역서(건축)'!R202 -> 0 | S35: =D35*'내역서(건축)'!S202 -> 0 | T35: =D35*'내역서(건축)'!T202 -> 0 | U35: =D35*'내역서(건축)'!U202 -> 0 | V35: =D35*'내역서(건축)'!V202 -> 0 | W35: =D35*'내역서(건축)'!W202 -> 0 | X35: =D35*'내역서(건축)'!X202 -> 0 | Y35: =D35*'내역서(건축)'!Y202 -> 0 | Z35: =D35*'내역서(건축)'!Z202 -> 0 | AA35: =D35*'내역서(건축)'!AA202 -> 0 | AB35: =D35*'내역서(건축)'!AB202 -> 0 | AC35: =D35*'내역서(건축)'!AC202 -> 0 | AD35: =D35*'내역서(건축)'!AD202 -> 0 | AE35: =D35*'내역서(건축)'!AE202 -> 0 | AF35: =D35*'내역서(건축)'!AF202 -> 0 | AG35: =D35*'내역서(건축)'!AG202 -> 0 | AH35: =D35*'내역서(건축)'!AH202 -> 0 | AI35: =D35*'내역서(건축)'!AI202 -> 0 | AJ35: =D35*'내역서(건축)'!AJ202 -> 0 | AK35: =D35*'내역서(건축)'!AK202 -> 0 | AL35: =D35*'내역서(건축)'!AL202 -> 0 | AM35: =D35*'내역서(건축)'!AM202 -> 0 | AN35: =D35*'내역서(건축)'!AN202 -> 0 | AO35: =D35*'내역서(건축)'!AO202 -> 0 | AP35: =D35*'내역서(건축)'!AP202 -> 0 | AQ35: =D35*'내역서(건축)'!AQ202 -> 0 | AR35: =D35*'내역서(건축)'!AR202 -> 0 | AS35: =D35*'내역서(건축)'!AS202 -> 0 | AT35: =D35*'내역서(건축)'!AT202 -> 0 | AU35: =D35*'내역서(건축)'!AU202 -> 0 | AV35: =D35*'내역서(건축)'!AV202 -> 0
A36: 9. 간판공사 | C36: 식 | D36: 1 | Q36: 1 | R36: =D36*'내역서(건축)'!R224 -> 0 | S36: =D36*'내역서(건축)'!S224 -> 0 | T36: =D36*'내역서(건축)'!T224 -> 0 | U36: =D36*'내역서(건축)'!U224 -> 0 | V36: =D36*'내역서(건축)'!V224 -> 0 | W36: =D36*'내역서(건축)'!W224 -> 0 | X36: =D36*'내역서(건축)'!X224 -> 0 | Y36: =D36*'내역서(건축)'!Y224 -> 0 | Z36: =D36*'내역서(건축)'!Z224 -> 0 | AA36: =D36*'내역서(건축)'!AA224 -> 0 | AB36: =D36*'내역서(건축)'!AB224 -> 0 | AC36: =D36*'내역서(건축)'!AC224 -> 0 | AD36: =D36*'내역서(건축)'!AD224 -> 0 | AE36: =D36*'내역서(건축)'!AE224 -> 0 | AF36: =D36*'내역서(건축)'!AF224 -> 0 | AG36: =D36*'내역서(건축)'!AG224 -> 0 | AH36: =D36*'내역서(건축)'!AH224 -> 0 | AI36: =D36*'내역서(건축)'!AI224 -> 0 | AJ36: =D36*'내역서(건축)'!AJ224 -> 0 | AK36: =D36*'내역서(건축)'!AK224 -> 0 | AL36: =D36*'내역서(건축)'!AL224 -> 0 | AM36: =D36*'내역서(건축)'!AM224 -> 0 | AN36: =D36*'내역서(건축)'!AN224 -> 0 | AO36: =D36*'내역서(건축)'!AO224 -> 0 | AP36: =D36*'내역서(건축)'!AP224 -> 0 | AQ36: =D36*'내역서(건축)'!AQ224 -> 0 | AR36: =D36*'내역서(건축)'!AR224 -> 0 | AS36: =D36*'내역서(건축)'!AS224 -> 0 | AT36: =D36*'내역서(건축)'!AT224 -> 0 | AU36: =D36*'내역서(건축)'!AU224 -> 0 | AV36: =D36*'내역서(건축)'!AV224 -> 0
A37: 10. 작업부신믈 | C37: 식 | D37: 1 | R37: =D37*'내역서(건축)'!R246 -> 0 | S37: =D37*'내역서(건축)'!S246 -> 0 | T37: =D37*'내역서(건축)'!T246 -> 0 | U37: =D37*'내역서(건축)'!U246 -> 0 | V37: =D37*'내역서(건축)'!V246 -> 0 | W37: =D37*'내역서(건축)'!W246 -> 0 | X37: =D37*'내역서(건축)'!X246 -> 0 | Y37: =D37*'내역서(건축)'!Y246 -> 0 | Z37: =D37*'내역서(건축)'!Z246 -> 0 | AA37: =D37*'내역서(건축)'!AA246 -> 0 | AB37: =D37*'내역서(건축)'!AB246 -> 0 | AC37: =D37*'내역서(건축)'!AC246 -> 0 | AD37: =D37*'내역서(건축)'!AD246 -> 0 | AE37: =D37*'내역서(건축)'!AE246 -> 0 | AF37: =D37*'내역서(건축)'!AF246 -> 0 | AG37: =D37*'내역서(건축)'!AG246 -> 0 | AH37: =D37*'내역서(건축)'!AH246 -> 0 | AI37: =D37*'내역서(건축)'!AI246 -> 0 | AJ37: =D37*'내역서(건축)'!AJ246 -> 0 | AK37: =D37*'내역서(건축)'!AK246 -> 0 | AL37: =D37*'내역서(건축)'!AL246 -> 0 | AM37: =D37*'내역서(건축)'!AM246 -> 0 | AN37: =D37*'내역서(건축)'!AN246 -> 0 | AO37: =D37*'내역서(건축)'!AO246 -> 0 | AP37: =D37*'내역서(건축)'!AP246 -> 0 | AQ37: =D37*'내역서(건축)'!AQ246 -> 0 | AR37: =D37*'내역서(건축)'!AR246 -> 0 | AS37: =D37*'내역서(건축)'!AS246 -> 0 | AT37: =D37*'내역서(건축)'!AT246 -> 0 | AU37: =D37*'내역서(건축)'!AU246 -> 0 | AV37: =D37*'내역서(건축)'!AV246 -> 0
A38: 11. 골재대 | C38: 식 | D38: 1 | Q38: 1 | R38: =D38*'내역서(건축)'!R268 -> 0 | S38: =D38*'내역서(건축)'!S268 -> 0 | T38: =D38*'내역서(건축)'!T268 -> 0 | U38: =D38*'내역서(건축)'!U268 -> 0 | V38: =D38*'내역서(건축)'!V268 -> 0 | W38: =D38*'내역서(건축)'!W268 -> 0 | X38: =D38*'내역서(건축)'!X268 -> 0 | Y38: =D38*'내역서(건축)'!Y268 -> 0 | Z38: =D38*'내역서(건축)'!Z268 -> 0 | AA38: =D38*'내역서(건축)'!AA268 -> 0 | AB38: =D38*'내역서(건축)'!AB268 -> 0 | AC38: =D38*'내역서(건축)'!AC268 -> 0 | AD38: =D38*'내역서(건축)'!AD268 -> 0 | AE38: =D38*'내역서(건축)'!AE268 -> 0 | AF38: =D38*'내역서(건축)'!AF268 -> 0 | AG38: =D38*'내역서(건축)'!AG268 -> 0 | AH38: =D38*'내역서(건축)'!AH268 -> 0 | AI38: =D38*'내역서(건축)'!AI268 -> 0 | AJ38: =D38*'내역서(건축)'!AJ268 -> 0 | AK38: =D38*'내역서(건축)'!AK268 -> 0 | AL38: =D38*'내역서(건축)'!AL268 -> 0 | AM38: =D38*'내역서(건축)'!AM268 -> 0 | AN38: =D38*'내역서(건축)'!AN268 -> 0 | AO38: =D38*'내역서(건축)'!AO268 -> 0 | AP38: =D38*'내역서(건축)'!AP268 -> 0 | AQ38: =D38*'내역서(건축)'!AQ268 -> 0 | AR38: =D38*'내역서(건축)'!AR268 -> 0 | AS38: =D38*'내역서(건축)'!AS268 -> 0 | AT38: =D38*'내역서(건축)'!AT268 -> 0 | AU38: =D38*'내역서(건축)'!AU268 -> 0 | AV38: =D38*'내역서(건축)'!AV268 -> 0
A48: 합 계 | F48: =SUMIF(Q28:Q38, "1", F28:F38) -> 0 | H48: =SUMIF(Q28:Q38, "1", H28:H38) -> 0 | J48: =SUMIF(Q28:Q38, "1", J28:J38) -> 0 | L48: =F48+H48+J48 -> 0 | R48: =SUM(R28:R38) -> 0 | S48: =SUM(S28:S38) -> 0 | T48: =SUM(T28:T38) -> 0 | U48: =SUM(U28:U38) -> 0 | V48: =SUM(V28:V38) -> 0 | W48: =SUM(W28:W38) -> 0 | X48: =SUM(X28:X38) -> 0 | Y48: =SUM(Y28:Y38) -> 0 | ... AY48: =SUM(AY28:AY38) -> 0

Sheet 집계표(기계)
A1: 공 종 별 집 계 표
A2: [ 전남고2026학년도AI융합형교육실구축(기계) ]
A3: 품 명 | B3: 규 격 | C3: 단위 | D3: 수량 | E3: 재 료 비 | G3: 노 무 비 | I3: 경 비 | K3: 합 계 | M3: 비 고 | N3: 공종코드 | O3: 변수 | P3: 상위공종 | Q3: 공종구분 | R3: 공종레벨 | S3: 공종소계 | T3: 원가계산서 연결금액
E4: 단 가 | F4: 금 액 | G4: 단 가 | H4: 금 액 | I4: 단 가 | J4: 금 액 | K4: 단 가 | L4: 금 액
A5: 전남고2026학년도AI융합형교육실구축(기계) | D5: 1 | N5: 01 | R5: 1
A6: 1.기계설비공사 | D6: 1 | N6: 0101 | P6: 01 | R6: 2
A7: 1-1.장비 및 위생기구 설치공사 | D7: 1 | N7: 010101 | P7: 0101 | R7: 3
A8: 1-2.급수, 급탕배관 설치공사 | D8: 1 | N8: 010102 | P8: 0101 | R8: 3
A9: 1-3.오수, 배수배관 설치공사 | D9: 1 | N9: 010103 | P9: 0101 | R9: 3
A10: 1-4.냉난방기 리모컨 이전 설치공사 | D10: 1 | N10: 010104 | P10: 0101 | R10: 3
A11: 1-5.철거 공사 | D11: 1 | N11: 010105 | P11: 0101 | R11: 3
A27: [ 합 계 ] | F27: =F5 -> 0 | H27: =H5 -> 0 | J27: =J5 -> 0 | L27: =L5 -> 0

Sheet 내역서(건축)
A1: 내 역 서
A2: 공사명 : 전남고 2026학년도 AI 융합형 교육실 구축
A3: 품 명 | B3: 규 격 | C3: 단위 | D3: 수 량 | E3: 재 료 비 | G3: 노 무 비 | I3: 경 비 | K3: 합 계 | M3: 비고
E4: 단 가 | F4: 금 액 | G4: 단 가 | H4: 금 액 | I4: 단 가 | J4: 금 액 | K4: 단 가 | L4: 금 액 | N4: 손료요율 | O4: 손료구분 | P4: 적용구분 | Q4: 합계구분 | R4: 기계경비 | S4: 운반비 | T4: 작업부산물 | U4: 관급 | V4: 외주비 | W4: 장비비 | X4: 폐기물처리비 | Y4: 가설비 | Z4: 잡비제외분 | AA4: 사급자재대 | AB4: 관급자재대 | AC4: 관급자관급 | AD4: 품질시험비 | AE4: 수도광열비 | AF4: 공기중석면농도측정비 | AG4: 사용자항목5 | AH4: 사용자항목6 | AI4: 사용자항목7 | AJ4: 관급자재대2 | AK4: 작업부산물 | AL4: 해체계획비및검토비 | AM4: 사용자항목11 | AN4: 사용자항목12 | AO4: 사용자항목13 | AP4: 사용자항목14 | AQ4: 사용자항목15 | AR4: 사용자항목16 | AS4: 사용자항목17 | AT4: 사용자항목18 | AU4: 사용자항목19 | AV4: 간접재료비 | AW4: 품목구분 | AX4: 조달코드 | AY4: 구분
A5: 1. 건축공사 > 1. 가설공사
A6: 강관 조립말비계(이동식)설치 및 해체 | B6: 높이 2m, 3개월 | C6: 대 | D6: 2 | M6: 일위 1호 | O6: ="" | P6: 기계경비 | Q6: 1 | R6: =IF(P6="기계경비", J6, 0) -> 0 | S6: =IF(P6="운반비", L6, 0) -> 0 | T6: =IF(P6="작업부산물", F6, 0) -> 0 | U6: =IF(P6="관급", F6, 0) -> 0 | V6: =IF(P6="외주비", J6, 0) -> 0 | W6: =IF(P6="장비비", J6, 0) -> 0 | X6: =IF(P6="폐기물처리비", L6, 0) -> 0 | Y6: =IF(P6="가설비", J6, 0) -> 0 | Z6: =IF(P6="잡비제외분", F6, 0) -> 0 | AA6: =IF(P6="사급자재대", L6, 0) -> 0 | AB6: =IF(P6="관급자재대", L6, 0) -> 0 | AC6: =IF(P6="관급자관급", L6, 0) -> 0 | AD6: =IF(P6="품질시험비", L6, 0) -> 0 | AE6: =IF(P6="수도광열비", L6, 0) -> 0 | AF6: =IF(P6="공기중석면농도측정비", L6, 0) -> 0 | AG6: =IF(P6="사용자항목5", L6, 0) -> 0 | AH6: =IF(P6="사용자항목6", L6, 0) -> 0 | AI6: =IF(P6="사용자항목7", L6, 0) -> 0 | AJ6: =IF(P6="관급자재대2", L6, 0) -> 0 | AK6: =IF(P6="작업부산물", L6, 0) -> 0 | AL6: =IF(P6="해체계획비및검토비", L6, 0) -> 0 | AM6: =IF(P6="사용자항목11", L6, 0) -> 0 | AN6: =IF(P6="사용자항목12", L6, 0) -> 0 | AO6: =IF(P6="사용자항목13", L6, 0) -> 0 | AP6: =IF(P6="사용자항목14", L6, 0) -> 0 | AQ6: =IF(P6="사용자항목15", L6, 0) -> 0 | AR6: =IF(P6="사용자항목16", L6, 0) -> 0 | AS6: =IF(P6="사용자항목17", L6, 0) -> 0 | AT6: =IF(P6="사용자항목18", L6, 0) -> 0 | AU6: =IF(P6="사용자항목19", L6, 0) -> 0
A7: 청렴현수막 설치 | B7: 시안제공 | C7: EA | D7: 1 | M7: 일위 2호 | O7: ="" | P7: 기계경비 | Q7: 1 | R7: =IF(P7="기계경비", J7, 0) -> 0 | S7: =IF(P7="운반비", L7, 0) -> 0 | T7: =IF(P7="작업부산물", F7, 0) -> 0 | U7: =IF(P7="관급", F7, 0) -> 0 | V7: =IF(P7="외주비", J7, 0) -> 0 | W7: =IF(P7="장비비", J7, 0) -> 0 | X7: =IF(P7="폐기물처리비", L7, 0) -> 0 | Y7: =IF(P7="가설비", J7, 0) -> 0 | Z7: =IF(P7="잡비제외분", F7, 0) -> 0 | AA7: =IF(P7="사급자재대", L7, 0) -> 0 | AB7: =IF(P7="관급자재대", L7, 0) -> 0 | AC7: =IF(P7="관급자관급", L7, 0) -> 0 | AD7: =IF(P7="품질시험비", L7, 0) -> 0 | AE7: =IF(P7="수도광열비", L7, 0) -> 0 | AF7: =IF(P7="공기중석면농도측정비", L7, 0) -> 0 | AG7: =IF(P7="사용자항목5", L7, 0) -> 0 | AH7: =IF(P7="사용자항목6", L7, 0) -> 0 | AI7: =IF(P7="사용자항목7", L7, 0) -> 0 | AJ7: =IF(P7="관급자재대2", L7, 0) -> 0 | AK7: =IF(P7="작업부산물", L7, 0) -> 0 | AL7: =IF(P7="해체계획비및검토비", L7, 0) -> 0 | AM7: =IF(P7="사용자항목11", L7, 0) -> 0 | AN7: =IF(P7="사용자항목12", L7, 0) -> 0 | AO7: =IF(P7="사용자항목13", L7, 0) -> 0 | AP7: =IF(P7="사용자항목14", L7, 0) -> 0 | AQ7: =IF(P7="사용자항목15", L7, 0) -> 0 | AR7: =IF(P7="사용자항목16", L7, 0) -> 0 | AS7: =IF(P7="사용자항목17", L7, 0) -> 0 | AT7: =IF(P7="사용자항목18", L7, 0) -> 0 | AU7: =IF(P7="사용자항목19", L7, 0) -> 0
A8: 건축허가표시판(공사현황) | B8: 600*900 이하, 철판+25각파이프 프레임 or 디지털실사 | C8: EA | D8: 1 | M8: 일위 3호 | O8: ="" | P8: 기계경비 | Q8: 1 | R8: =IF(P8="기계경비", J8, 0) -> 0 | S8: =IF(P8="운반비", L8, 0) -> 0 | T8: =IF(P8="작업부산물", F8, 0) -> 0 | U8: =IF(P8="관급", F8, 0) -> 0 | V8: =IF(P8="외주비", J8, 0) -> 0 | W8: =IF(P8="장비비", J8, 0) -> 0 | X8: =IF(P8="폐기물처리비", L8, 0) -> 0 | Y8: =IF(P8="가설비", J8, 0) -> 0 | Z8: =IF(P8="잡비제외분", F8, 0) -> 0 | AA8: =IF(P8="사급자재대", L8, 0) -> 0 | AB8: =IF(P8="관급자재대", L8, 0) -> 0 | AC8: =IF(P8="관급자관급", L8, 0) -> 0 | AD8: =IF(P8="품질시험비", L8, 0) -> 0 | AE8: =IF(P8="수도광열비", L8, 0) -> 0 | AF8: =IF(P8="공기중석면농도측정비", L8, 0) -> 0 | AG8: =IF(P8="사용자항목5", L8, 0) -> 0 | AH8: =IF(P8="사용자항목6", L8, 0) -> 0 | AI8: =IF(P8="사용자항목7", L8, 0) -> 0 | AJ8: =IF(P8="관급자재대2", L8, 0) -> 0 | AK8: =IF(P8="작업부산물", L8, 0) -> 0 | AL8: =IF(P8="해체계획비및검토비", L8, 0) -> 0 | AM8: =IF(P8="사용자항목11", L8, 0) -> 0 | AN8: =IF(P8="사용자항목12", L8, 0) -> 0 | AO8: =IF(P8="사용자항목13", L8, 0) -> 0 | AP8: =IF(P8="사용자항목14", L8, 0) -> 0 | AQ8: =IF(P8="사용자항목15", L8, 0) -> 0 | AR8: =IF(P8="사용자항목16", L8, 0) -> 0 | AS8: =IF(P8="사용자항목17", L8, 0) -> 0 | AT8: =IF(P8="사용자항목18", L8, 0) -> 0 | AU8: =IF(P8="사용자항목19", L8, 0) -> 0
A9: 공사용가설벽 설치 및 해체(내부통행안전시설) | B9: 틀+합판4.8mm | C9: M2 | D9: 6.2 | M9: 일위 4호 | O9: ="" | P9: 기계경비 | Q9: 1 | R9: =IF(P9="기계경비", J9, 0) -> 0 | S9: =IF(P9="운반비", L9, 0) -> 0 | T9: =IF(P9="작업부산물", F9, 0) -> 0 | U9: =IF(P9="관급", F9, 0) -> 0 | V9: =IF(P9="외주비", J9, 0) -> 0 | W9: =IF(P9="장비비", J9, 0) -> 0 | X9: =IF(P9="폐기물처리비", L9, 0) -> 0 | Y9: =IF(P9="가설비", J9, 0) -> 0 | Z9: =IF(P9="잡비제외분", F9, 0) -> 0 | AA9: =IF(P9="사급자재대", L9, 0) -> 0 | AB9: =IF(P9="관급자재대", L9, 0) -> 0 | AC9: =IF(P9="관급자관급", L9, 0) -> 0 | AD9: =IF(P9="품질시험비", L9, 0) -> 0 | AE9: =IF(P9="수도광열비", L9, 0) -> 0 | AF9: =IF(P9="공기중석면농도측정비", L9, 0) -> 0 | AG9: =IF(P9="사용자항목5", L9, 0) -> 0 | AH9: =IF(P9="사용자항목6", L9, 0) -> 0 | AI9: =IF(P9="사용자항목7", L9, 0) -> 0 | AJ9: =IF(P9="관급자재대2", L9, 0) -> 0 | AK9: =IF(P9="작업부산물", L9, 0) -> 0 | AL9: =IF(P9="해체계획비및검토비", L9, 0) -> 0 | AM9: =IF(P9="사용자항목11", L9, 0) -> 0 | AN9: =IF(P9="사용자항목12", L9, 0) -> 0 | AO9: =IF(P9="사용자항목13", L9, 0) -> 0 | AP9: =IF(P9="사용자항목14", L9, 0) -> 0 | AQ9: =IF(P9="사용자항목15", L9, 0) -> 0 | AR9: =IF(P9="사용자항목16", L9, 0) -> 0 | AS9: =IF(P9="사용자항목17", L9, 0) -> 0 | AT9: =IF(P9="사용자항목18", L9, 0) -> 0 | AU9: =IF(P9="사용자항목19", L9, 0) -> 0
A10: 건축물현장정리 | B10: 보통인부,집기이설및재설치 | C10: 인 | D10: 7 | M10: 일위 5호 | O10: ="" | P10: 기계경비 | Q10: 1 | R10: =IF(P10="기계경비", J10, 0) -> 0 | S10: =IF(P10="운반비", L10, 0) -> 0 | T10: =IF(P10="작업부산물", F10, 0) -> 0 | U10: =IF(P10="관급", F10, 0) -> 0 | V10: =IF(P10="외주비", J10, 0) -> 0 | W10: =IF(P10="장비비", J10, 0) -> 0 | X10: =IF(P10="폐기물처리비", L10, 0) -> 0 | Y10: =IF(P10="가설비", J10, 0) -> 0 | Z10: =IF(P10="잡비제외분", F10, 0) -> 0 | AA10: =IF(P10="사급자재대", L10, 0) -> 0 | AB10: =IF(P10="관급자재대", L10, 0) -> 0 | AC10: =IF(P10="관급자관급", L10, 0) -> 0 | AD10: =IF(P10="품질시험비", L10, 0) -> 0 | AE10: =IF(P10="수도광열비", L10, 0) -> 0 | AF10: =IF(P10="공기중석면농도측정비", L10, 0) -> 0 | AG10: =IF(P10="사용자항목5", L10, 0) -> 0 | AH10: =IF(P10="사용자항목6", L10, 0) -> 0 | AI10: =IF(P10="사용자항목7", L10, 0) -> 0 | AJ10: =IF(P10="관급자재대2", L10, 0) -> 0 | AK10: =IF(P10="작업부산물", L10, 0) -> 0 | AL10: =IF(P10="해체계획비및검토비", L10, 0) -> 0 | AM10: =IF(P10="사용자항목11", L10, 0) -> 0 | AN10: =IF(P10="사용자항목12", L10, 0) -> 0 | AO10: =IF(P10="사용자항목13", L10, 0) -> 0 | AP10: =IF(P10="사용자항목14", L10, 0) -> 0 | AQ10: =IF(P10="사용자항목15", L10, 0) -> 0 | AR10: =IF(P10="사용자항목16", L10, 0) -> 0 | AS10: =IF(P10="사용자항목17", L10, 0) -> 0 | AT10: =IF(P10="사용자항목18", L10, 0) -> 0 | AU10: =IF(P10="사용자항목19", L10, 0) -> 0 | AY10: KDJ
A11: 건축물현장정리 | B11: 보통인부 | C11: 인 | D11: 2 | M11: 일위 6호 | O11: ="" | P11: 기계경비 | Q11: 1 | R11: =IF(P11="기계경비", J11, 0) -> 0 | S11: =IF(P11="운반비", L11, 0) -> 0 | T11: =IF(P11="작업부산물", F11, 0) -> 0 | U11: =IF(P11="관급", F11, 0) -> 0 | V11: =IF(P11="외주비", J11, 0) -> 0 | W11: =IF(P11="장비비", J11, 0) -> 0 | X11: =IF(P11="폐기물처리비", L11, 0) -> 0 | Y11: =IF(P11="가설비", J11, 0) -> 0 | Z11: =IF(P11="잡비제외분", F11, 0) -> 0 | AA11: =IF(P11="사급자재대", L11, 0) -> 0 | AB11: =IF(P11="관급자재대", L11, 0) -> 0 | AC11: =IF(P11="관급자관급", L11, 0) -> 0 | AD11: =IF(P11="품질시험비", L11, 0) -> 0 | AE11: =IF(P11="수도광열비", L11, 0) -> 0 | AF11: =IF(P11="공기중석면농도측정비", L11, 0) -> 0 | AG11: =IF(P11="사용자항목5", L11, 0) -> 0 | AH11: =IF(P11="사용자항목6", L11, 0) -> 0 | AI11: =IF(P11="사용자항목7", L11, 0) -> 0 | AJ11: =IF(P11="관급자재대2", L11, 0) -> 0 | AK11: =IF(P11="작업부산물", L11, 0) -> 0 | AL11: =IF(P11="해체계획비및검토비", L11, 0) -> 0 | AM11: =IF(P11="사용자항목11", L11, 0) -> 0 | AN11: =IF(P11="사용자항목12", L11, 0) -> 0 | AO11: =IF(P11="사용자항목13", L11, 0) -> 0 | AP11: =IF(P11="사용자항목14", L11, 0) -> 0 | AQ11: =IF(P11="사용자항목15", L11, 0) -> 0 | AR11: =IF(P11="사용자항목16", L11, 0) -> 0 | AS11: =IF(P11="사용자항목17", L11, 0) -> 0 | AT11: =IF(P11="사용자항목18", L11, 0) -> 0 | AU11: =IF(P11="사용자항목19", L11, 0) -> 0 | AY11: KDJ
A26: 합 계 | F26: =ROUNDDOWN(SUMIF(Q6:Q25, "1", F6:F25), 0) -> 0 | H26: =ROUNDDOWN(SUMIF(Q6:Q25, "1", H6:H25), 0) -> 0 | J26: =ROUNDDOWN(SUMIF(Q6:Q25, "1", J6:J25), 0) -> 0 | L26: =F26+H26+J26 -> 0 | R26: =ROUNDDOWN(SUM(R6:R11), 0) -> 0 | S26: =ROUNDDOWN(SUM(S6:S11), 0) -> 0 | T26: =ROUNDDOWN(SUM(T6:T11), 0) -> 0 | U26: =ROUNDDOWN(SUM(U6:U11), 0) -> 0 | V26: =ROUNDDOWN(SUM(V6:V11), 0) -> 0 | W26: =ROUNDDOWN(SUM(W6:W11), 0) -> 0 | X26: =ROUNDDOWN(SUM(X6:X11), 0) -> 0 | Y26: =ROUNDDOWN(SUM(Y6:Y11), 0) -> 0 | ... AY26: =ROUNDDOWN(SUM(AY6:AY11), 0) -> 0
A27: 1. 건축공사 > 2. 창호공사
A28: SSD01 | B28: 1.7*2.1 | C28: 개소 | D28: 1 | M28: 일위 7호 | O28: ="" | P28: 기계경비 | Q28: 1 | R28: =IF(P28="기계경비", J28, 0) -> 0 | S28: =IF(P28="운반비", L28, 0) -> 0 | T28: =IF(P28="작업부산물", F28, 0) -> 0 | U28: =IF(P28="관급", F28, 0) -> 0 | V28: =IF(P28="외주비", J28, 0) -> 0 | W28: =IF(P28="장비비", J28, 0) -> 0 | X28: =IF(P28="폐기물처리비", L28, 0) -> 0 | Y28: =IF(P28="가설비", J28, 0) -> 0 | Z28: =IF(P28="잡비제외분", F28, 0) -> 0 | AA28: =IF(P28="사급자재대", L28, 0) -> 0 | AB28: =IF(P28="관급자재대", L28, 0) -> 0 | AC28: =IF(P28="관급자관급", L28, 0) -> 0 | AD28: =IF(P28="품질시험비", L28, 0) -> 0 | AE28: =IF(P28="수도광열비", L28, 0) -> 0 | AF28: =IF(P28="공기중석면농도측정비", L28, 0) -> 0 | AG28: =IF(P28="사용자항목5", L28, 0) -> 0 | AH28: =IF(P28="사용자항목6", L28, 0) -> 0 | AI28: =IF(P28="사용자항목7", L28, 0) -> 0 | AJ28: =IF(P28="관급자재대2", L28, 0) -> 0 | AK28: =IF(P28="작업부산물", L28, 0) -> 0 | AL28: =IF(P28="해체계획비및검토비", L28, 0) -> 0 | AM28: =IF(P28="사용자항목11", L28, 0) -> 0 | AN28: =IF(P28="사용자항목12", L28, 0) -> 0 | AO28: =IF(P28="사용자항목13", L28, 0) -> 0 | AP28: =IF(P28="사용자항목14", L28, 0) -> 0 | AQ28: =IF(P28="사용자항목15", L28, 0) -> 0 | AR28: =IF(P28="사용자항목16", L28, 0) -> 0 | AS28: =IF(P28="사용자항목17", L28, 0) -> 0 | AT28: =IF(P28="사용자항목18", L28, 0) -> 0 | AU28: =IF(P28="사용자항목19", L28, 0) -> 0
A29: WD01 | B29: 0.9*2.1 | C29: 개소 | D29: 1 | M29: 일위 8호 | O29: ="" | P29: 기계경비 | Q29: 1 | R29: =IF(P29="기계경비", J29, 0) -> 0 | S29: =IF(P29="운반비", L29, 0) -> 0 | T29: =IF(P29="작업부산물", F29, 0) -> 0 | U29: =IF(P29="관급", F29, 0) -> 0 | V29: =IF(P29="외주비", J29, 0) -> 0 | W29: =IF(P29="장비비", J29, 0) -> 0 | X29: =IF(P29="폐기물처리비", L29, 0) -> 0 | Y29: =IF(P29="가설비", J29, 0) -> 0 | Z29: =IF(P29="잡비제외분", F29, 0) -> 0 | AA29: =IF(P29="사급자재대", L29, 0) -> 0 | AB29: =IF(P29="관급자재대", L29, 0) -> 0 | AC29: =IF(P29="관급자관급", L29, 0) -> 0 | AD29: =IF(P29="품질시험비", L29, 0) -> 0 | AE29: =IF(P29="수도광열비", L29, 0) -> 0 | AF29: =IF(P29="공기중석면농도측정비", L29, 0) -> 0 | AG29: =IF(P29="사용자항목5", L29, 0) -> 0 | AH29: =IF(P29="사용자항목6", L29, 0) -> 0 | AI29: =IF(P29="사용자항목7", L29, 0) -> 0 | AJ29: =IF(P29="관급자재대2", L29, 0) -> 0 | AK29: =IF(P29="작업부산물", L29, 0) -> 0 | AL29: =IF(P29="해체계획비및검토비", L29, 0) -> 0 | AM29: =IF(P29="사용자항목11", L29, 0) -> 0 | AN29: =IF(P29="사용자항목12", L29, 0) -> 0 | AO29: =IF(P29="사용자항목13", L29, 0) -> 0 | AP29: =IF(P29="사용자항목14", L29, 0) -> 0 | AQ29: =IF(P29="사용자항목15", L29, 0) -> 0 | AR29: =IF(P29="사용자항목16", L29, 0) -> 0 | AS29: =IF(P29="사용자항목17", L29, 0) -> 0 | AT29: =IF(P29="사용자항목18", L29, 0) -> 0 | AU29: =IF(P29="사용자항목19", L29, 0) -> 0
A30: 도아록설치 | B30: 원통형(목재문) | C30: 개소 | D30: 1 | M30: 일위 9호 | O30: ="" | P30: 기계경비 | Q30: 1 | R30: =IF(P30="기계경비", J30, 0) -> 0 | S30: =IF(P30="운반비", L30, 0) -> 0 | T30: =IF(P30="작업부산물", F30, 0) -> 0 | U30: =IF(P30="관급", F30, 0) -> 0 | V30: =IF(P30="외주비", J30, 0) -> 0 | W30: =IF(P30="장비비", J30, 0) -> 0 | X30: =IF(P30="폐기물처리비", L30, 0) -> 0 | Y30: =IF(P30="가설비", J30, 0) -> 0 | Z30: =IF(P30="잡비제외분", F30, 0) -> 0 | AA30: =IF(P30="사급자재대", L30, 0) -> 0 | AB30: =IF(P30="관급자재대", L30, 0) -> 0 | AC30: =IF(P30="관급자관급", L30, 0) -> 0 | AD30: =IF(P30="품질시험비", L30, 0) -> 0 | AE30: =IF(P30="수도광열비", L30, 0) -> 0 | AF30: =IF(P30="공기중석면농도측정비", L30, 0) -> 0 | AG30: =IF(P30="사용자항목5", L30, 0) -> 0 | AH30: =IF(P30="사용자항목6", L30, 0) -> 0 | AI30: =IF(P30="사용자항목7", L30, 0) -> 0 | AJ30: =IF(P30="관급자재대2", L30, 0) -> 0 | AK30: =IF(P30="작업부산물", L30, 0) -> 0 | AL30: =IF(P30="해체계획비및검토비", L30, 0) -> 0 | AM30: =IF(P30="사용자항목11", L30, 0) -> 0 | AN30: =IF(P30="사용자항목12", L30, 0) -> 0 | AO30: =IF(P30="사용자항목13", L30, 0) -> 0 | AP30: =IF(P30="사용자항목14", L30, 0) -> 0 | AQ30: =IF(P30="사용자항목15", L30, 0) -> 0 | AR30: =IF(P30="사용자항목16", L30, 0) -> 0 | AS30: =IF(P30="사용자항목17", L30, 0) -> 0 | AT30: =IF(P30="사용자항목18", L30, 0) -> 0 | AU30: =IF(P30="사용자항목19", L30, 0) -> 0
A31: 도어힌지 | B31: 도어힌지, 황동경첩, 3.0T×102×102mm | C31: 개 | D31: 3 | O31: ="01" -> 01 | P31: 기계경비 | Q31: 1 | R31: =IF(P31="기계경비", J31, 0) -> 0 | S31: =IF(P31="운반비", L31, 0) -> 0 | T31: =IF(P31="작업부산물", F31, 0) -> 0 | U31: =IF(P31="관급", F31, 0) -> 0 | V31: =IF(P31="외주비", J31, 0) -> 0 | W31: =IF(P31="장비비", J31, 0) -> 0 | X31: =IF(P31="폐기물처리비", L31, 0) -> 0 | Y31: =IF(P31="가설비", J31, 0) -> 0 | Z31: =IF(P31="잡비제외분", F31, 0) -> 0 | AA31: =IF(P31="사급자재대", L31, 0) -> 0 | AB31: =IF(P31="관급자재대", L31, 0) -> 0 | AC31: =IF(P31="관급자관급", L31, 0) -> 0 | AD31: =IF(P31="품질시험비", L31, 0) -> 0 | AE31: =IF(P31="수도광열비", L31, 0) -> 0 | AF31: =IF(P31="공기중석면농도측정비", L31, 0) -> 0 | AG31: =IF(P31="사용자항목5", L31, 0) -> 0 | AH31: =IF(P31="사용자항목6", L31, 0) -> 0 | AI31: =IF(P31="사용자항목7", L31, 0) -> 0 | AJ31: =IF(P31="관급자재대2", L31, 0) -> 0 | AK31: =IF(P31="작업부산물", L31, 0) -> 0 | AL31: =IF(P31="해체계획비및검토비", L31, 0) -> 0 | AM31: =IF(P31="사용자항목11", L31, 0) -> 0 | AN31: =IF(P31="사용자항목12", L31, 0) -> 0 | AO31: =IF(P31="사용자항목13", L31, 0) -> 0 | AP31: =IF(P31="사용자항목14", L31, 0) -> 0 | AQ31: =IF(P31="사용자항목15", L31, 0) -> 0 | AR31: =IF(P31="사용자항목16", L31, 0) -> 0 | AS31: =IF(P31="사용자항목17", L31, 0) -> 0 | AT31: =IF(P31="사용자항목18", L31, 0) -> 0 | AU31: =IF(P31="사용자항목19", L31, 0) -> 0
A32: 세이프강화도어(락2000형) - 내부용 | B32: 12* 850*2100mm, 투명,손보호용,헤어라인/밀러 | C32: 개 | D32: 2 | M32: 일위 10호 | O32: ="" | P32: 기계경비 | Q32: 1 | R32: =IF(P32="기계경비", J32, 0) -> 0 | S32: =IF(P32="운반비", L32, 0) -> 0 | T32: =IF(P32="작업부산물", F32, 0) -> 0 | U32: =IF(P32="관급", F32, 0) -> 0 | V32: =IF(P32="외주비", J32, 0) -> 0 | W32: =IF(P32="장비비", J32, 0) -> 0 | X32: =IF(P32="폐기물처리비", L32, 0) -> 0 | Y32: =IF(P32="가설비", J32, 0) -> 0 | Z32: =IF(P32="잡비제외분", F32, 0) -> 0 | AA32: =IF(P32="사급자재대", L32, 0) -> 0 | AB32: =IF(P32="관급자재대", L32, 0) -> 0 | AC32: =IF(P32="관급자관급", L32, 0) -> 0 | AD32: =IF(P32="품질시험비", L32, 0) -> 0 | AE32: =IF(P32="수도광열비", L32, 0) -> 0 | AF32: =IF(P32="공기중석면농도측정비", L32, 0) -> 0 | AG32: =IF(P32="사용자항목5", L32, 0) -> 0 | AH32: =IF(P32="사용자항목6", L32, 0) -> 0 | AI32: =IF(P32="사용자항목7", L32, 0) -> 0 | AJ32: =IF(P32="관급자재대2", L32, 0) -> 0 | AK32: =IF(P32="작업부산물", L32, 0) -> 0 | AL32: =IF(P32="해체계획비및검토비", L32, 0) -> 0 | AM32: =IF(P32="사용자항목11", L32, 0) -> 0 | AN32: =IF(P32="사용자항목12", L32, 0) -> 0 | AO32: =IF(P32="사용자항목13", L32, 0) -> 0 | AP32: =IF(P32="사용자항목14", L32, 0) -> 0 | AQ32: =IF(P32="사용자항목15", L32, 0) -> 0 | AR32: =IF(P32="사용자항목16", L32, 0) -> 0 | AS32: =IF(P32="사용자항목17", L32, 0) -> 0 | AT32: =IF(P32="사용자항목18", L32, 0) -> 0 | AU32: =IF(P32="사용자항목19", L32, 0) -> 0 | AY32: KDJ
A33: 플로어힌지(강화유리문) 설치 | B33: 105kg | C33: 개소 | D33: 2 | M33: 일위 11호 | O33: ="" | P33: 기계경비 | Q33: 1 | R33: =IF(P33="기계경비", J33, 0) -> 0 | S33: =IF(P33="운반비", L33, 0) -> 0 | T33: =IF(P33="작업부산물", F33, 0) -> 0 | U33: =IF(P33="관급", F33, 0) -> 0 | V33: =IF(P33="외주비", J33, 0) -> 0 | W33: =IF(P33="장비비", J33, 0) -> 0 | X33: =IF(P33="폐기물처리비", L33, 0) -> 0 | Y33: =IF(P33="가설비", J33, 0) -> 0 | Z33: =IF(P33="잡비제외분", F33, 0) -> 0 | AA33: =IF(P33="사급자재대", L33, 0) -> 0 | AB33: =IF(P33="관급자재대", L33, 0) -> 0 | AC33: =IF(P33="관급자관급", L33, 0) -> 0 | AD33: =IF(P33="품질시험비", L33, 0) -> 0 | AE33: =IF(P33="수도광열비", L33, 0) -> 0 | AF33: =IF(P33="공기중석면농도측정비", L33, 0) -> 0 | AG33: =IF(P33="사용자항목5", L33, 0) -> 0 | AH33: =IF(P33="사용자항목6", L33, 0) -> 0 | AI33: =IF(P33="사용자항목7", L33, 0) -> 0 | AJ33: =IF(P33="관급자재대2", L33, 0) -> 0 | AK33: =IF(P33="작업부산물", L33, 0) -> 0 | AL33: =IF(P33="해체계획비및검토비", L33, 0) -> 0 | AM33: =IF(P33="사용자항목11", L33, 0) -> 0 | AN33: =IF(P33="사용자항목12", L33, 0) -> 0 | AO33: =IF(P33="사용자항목13", L33, 0) -> 0 | AP33: =IF(P33="사용자항목14", L33, 0) -> 0 | AQ33: =IF(P33="사용자항목15", L33, 0) -> 0 | AR33: =IF(P33="사용자항목16", L33, 0) -> 0 | AS33: =IF(P33="사용자항목17", L33, 0) -> 0 | AT33: =IF(P33="사용자항목18", L33, 0) -> 0 | AU33: =IF(P33="사용자항목19", L33, 0) -> 0
A34: 강화유리문틀 | B34: 도어부자재, 스텐손잡이 | C34: EA | D34: 2 | O34: ="01" -> 01 | P34: 기계경비 | Q34: 1 | R34: =IF(P34="기계경비", J34, 0) -> 0 | S34: =IF(P34="운반비", L34, 0) -> 0 | T34: =IF(P34="작업부산물", F34, 0) -> 0 | U34: =IF(P34="관급", F34, 0) -> 0 | V34: =IF(P34="외주비", J34, 0) -> 0 | W34: =IF(P34="장비비", J34, 0) -> 0 | X34: =IF(P34="폐기물처리비", L34, 0) -> 0 | Y34: =IF(P34="가설비", J34, 0) -> 0 | Z34: =IF(P34="잡비제외분", F34, 0) -> 0 | AA34: =IF(P34="사급자재대", L34, 0) -> 0 | AB34: =IF(P34="관급자재대", L34, 0) -> 0 | AC34: =IF(P34="관급자관급", L34, 0) -> 0 | AD34: =IF(P34="품질시험비", L34, 0) -> 0 | AE34: =IF(P34="수도광열비", L34, 0) -> 0 | AF34: =IF(P34="공기중석면농도측정비", L34, 0) -> 0 | AG34: =IF(P34="사용자항목5", L34, 0) -> 0 | AH34: =IF(P34="사용자항목6", L34, 0) -> 0 | AI34: =IF(P34="사용자항목7", L34, 0) -> 0 | AJ34: =IF(P34="관급자재대2", L34, 0) -> 0 | AK34: =IF(P34="작업부산물", L34, 0) -> 0 | AL34: =IF(P34="해체계획비및검토비", L34, 0) -> 0 | AM34: =IF(P34="사용자항목11", L34, 0) -> 0 | AN34: =IF(P34="사용자항목12", L34, 0) -> 0 | AO34: =IF(P34="사용자항목13", L34, 0) -> 0 | AP34: =IF(P34="사용자항목14", L34, 0) -> 0 | AQ34: =IF(P34="사용자항목15", L34, 0) -> 0 | AR34: =IF(P34="사용자항목16", L34, 0) -> 0 | AS34: =IF(P34="사용자항목17", L34, 0) -> 0 | AT34: =IF(P34="사용자항목18", L34, 0) -> 0 | AU34: =IF(P34="사용자항목19", L34, 0) -> 0
A35: 디지털도어록 설치 | B35: 터치패드번호+카드+비상키 | C35: 개소 | D35: 1 | M35: 일위 12호 | O35: ="" | P35: 기계경비 | Q35: 1 | R35: =IF(P35="기계경비", J35, 0) -> 0 | S35: =IF(P35="운반비", L35, 0) -> 0 | T35: =IF(P35="작업부산물", F35, 0) -> 0 | U35: =IF(P35="관급", F35, 0) -> 0 | V35: =IF(P35="외주비", J35, 0) -> 0 | W35: =IF(P35="장비비", J35, 0) -> 0 | X35: =IF(P35="폐기물처리비", L35, 0) -> 0 | Y35: =IF(P35="가설비", J35, 0) -> 0 | Z35: =IF(P35="잡비제외분", F35, 0) -> 0 | AA35: =IF(P35="사급자재대", L35, 0) -> 0 | AB35: =IF(P35="관급자재대", L35, 0) -> 0 | AC35: =IF(P35="관급자관급", L35, 0) -> 0 | AD35: =IF(P35="품질시험비", L35, 0) -> 0 | AE35: =IF(P35="수도광열비", L35, 0) -> 0 | AF35: =IF(P35="공기중석면농도측정비", L35, 0) -> 0 | AG35: =IF(P35="사용자항목5", L35, 0) -> 0 | AH35: =IF(P35="사용자항목6", L35, 0) -> 0 | AI35: =IF(P35="사용자항목7", L35, 0) -> 0 | AJ35: =IF(P35="관급자재대2", L35, 0) -> 0 | AK35: =IF(P35="작업부산물", L35, 0) -> 0 | AL35: =IF(P35="해체계획비및검토비", L35, 0) -> 0 | AM35: =IF(P35="사용자항목11", L35, 0) -> 0 | AN35: =IF(P35="사용자항목12", L35, 0) -> 0 | AO35: =IF(P35="사용자항목13", L35, 0) -> 0 | AP35: =IF(P35="사용자항목14", L35, 0) -> 0 | AQ35: =IF(P35="사용자항목15", L35, 0) -> 0 | AR35: =IF(P35="사용자항목16", L35, 0) -> 0 | AS35: =IF(P35="사용자항목17", L35, 0) -> 0 | AT35: =IF(P35="사용자항목18", L35, 0) -> 0 | AU35: =IF(P35="사용자항목19", L35, 0) -> 0 | AY35: KDJ
A36: 스텐레스재료분리대 | B36: 바닥, W30×H20×1.5t | C36: m | D36: 1.7 | M36: 일위 13호 | O36: ="" | P36: 기계경비 | Q36: 1 | R36: =IF(P36="기계경비", J36, 0) -> 0 | S36: =IF(P36="운반비", L36, 0) -> 0 | T36: =IF(P36="작업부산물", F36, 0) -> 0 | U36: =IF(P36="관급", F36, 0) -> 0 | V36: =IF(P36="외주비", J36, 0) -> 0 | W36: =IF(P36="장비비", J36, 0) -> 0 | X36: =IF(P36="폐기물처리비", L36, 0) -> 0 | Y36: =IF(P36="가설비", J36, 0) -> 0 | Z36: =IF(P36="잡비제외분", F36, 0) -> 0 | AA36: =IF(P36="사급자재대", L36, 0) -> 0 | AB36: =IF(P36="관급자재대", L36, 0) -> 0 | AC36: =IF(P36="관급자관급", L36, 0) -> 0 | AD36: =IF(P36="품질시험비", L36, 0) -> 0 | AE36: =IF(P36="수도광열비", L36, 0) -> 0 | AF36: =IF(P36="공기중석면농도측정비", L36, 0) -> 0 | AG36: =IF(P36="사용자항목5", L36, 0) -> 0 | AH36: =IF(P36="사용자항목6", L36, 0) -> 0 | AI36: =IF(P36="사용자항목7", L36, 0) -> 0 | AJ36: =IF(P36="관급자재대2", L36, 0) -> 0 | AK36: =IF(P36="작업부산물", L36, 0) -> 0 | AL36: =IF(P36="해체계획비및검토비", L36, 0) -> 0 | AM36: =IF(P36="사용자항목11", L36, 0) -> 0 | AN36: =IF(P36="사용자항목12", L36, 0) -> 0 | AO36: =IF(P36="사용자항목13", L36, 0) -> 0 | AP36: =IF(P36="사용자항목14", L36, 0) -> 0 | AQ36: =IF(P36="사용자항목15", L36, 0) -> 0 | AR36: =IF(P36="사용자항목16", L36, 0) -> 0 | AS36: =IF(P36="사용자항목17", L36, 0) -> 0 | AT36: =IF(P36="사용자항목18", L36, 0) -> 0 | AU36: =IF(P36="사용자항목19", L36, 0) -> 0
A37: 수밀코킹(실리콘) | B37: 삼각, 10mm, 창호주위 | C37: M | D37: 22 | M37: 일위 14호 | O37: ="" | P37: 기계경비 | Q37: 1 | R37: =IF(P37="기계경비", J37, 0) -> 0 | S37: =IF(P37="운반비", L37, 0) -> 0 | T37: =IF(P37="작업부산물", F37, 0) -> 0 | U37: =IF(P37="관급", F37, 0) -> 0 | V37: =IF(P37="외주비", J37, 0) -> 0 | W37: =IF(P37="장비비", J37, 0) -> 0 | X37: =IF(P37="폐기물처리비", L37, 0) -> 0 | Y37: =IF(P37="가설비", J37, 0) -> 0 | Z37: =IF(P37="잡비제외분", F37, 0) -> 0 | AA37: =IF(P37="사급자재대", L37, 0) -> 0 | AB37: =IF(P37="관급자재대", L37, 0) -> 0 | AC37: =IF(P37="관급자관급", L37, 0) -> 0 | AD37: =IF(P37="품질시험비", L37, 0) -> 0 | AE37: =IF(P37="수도광열비", L37, 0) -> 0 | AF37: =IF(P37="공기중석면농도측정비", L37, 0) -> 0 | AG37: =IF(P37="사용자항목5", L37, 0) -> 0 | AH37: =IF(P37="사용자항목6", L37, 0) -> 0 | AI37: =IF(P37="사용자항목7", L37, 0) -> 0 | AJ37: =IF(P37="관급자재대2", L37, 0) -> 0 | AK37: =IF(P37="작업부산물", L37, 0) -> 0 | AL37: =IF(P37="해체계획비및검토비", L37, 0) -> 0 | AM37: =IF(P37="사용자항목11", L37, 0) -> 0 | AN37: =IF(P37="사용자항목12", L37, 0) -> 0 | AO37: =IF(P37="사용자항목13", L37, 0) -> 0 | AP37: =IF(P37="사용자항목14", L37, 0) -> 0 | AQ37: =IF(P37="사용자항목15", L37, 0) -> 0 | AR37: =IF(P37="사용자항목16", L37, 0) -> 0 | AS37: =IF(P37="사용자항목17", L37, 0) -> 0 | AT37: =IF(P37="사용자항목18", L37, 0) -> 0 | AU37: =IF(P37="사용자항목19", L37, 0) -> 0
A38: 창호주위 모르타르 충전 | C38: M | D38: 11 | M38: 일위 15호 | O38: ="" | P38: 기계경비 | Q38: 1 | R38: =IF(P38="기계경비", J38, 0) -> 0 | S38: =IF(P38="운반비", L38, 0) -> 0 | T38: =IF(P38="작업부산물", F38, 0) -> 0 | U38: =IF(P38="관급", F38, 0) -> 0 | V38: =IF(P38="외주비", J38, 0) -> 0 | W38: =IF(P38="장비비", J38, 0) -> 0 | X38: =IF(P38="폐기물처리비", L38, 0) -> 0 | Y38: =IF(P38="가설비", J38, 0) -> 0 | Z38: =IF(P38="잡비제외분", F38, 0) -> 0 | AA38: =IF(P38="사급자재대", L38, 0) -> 0 | AB38: =IF(P38="관급자재대", L38, 0) -> 0 | AC38: =IF(P38="관급자관급", L38, 0) -> 0 | AD38: =IF(P38="품질시험비", L38, 0) -> 0 | AE38: =IF(P38="수도광열비", L38, 0) -> 0 | AF38: =IF(P38="공기중석면농도측정비", L38, 0) -> 0 | AG38: =IF(P38="사용자항목5", L38, 0) -> 0 | AH38: =IF(P38="사용자항목6", L38, 0) -> 0 | AI38: =IF(P38="사용자항목7", L38, 0) -> 0 | AJ38: =IF(P38="관급자재대2", L38, 0) -> 0 | AK38: =IF(P38="작업부산물", L38, 0) -> 0 | AL38: =IF(P38="해체계획비및검토비", L38, 0) -> 0 | AM38: =IF(P38="사용자항목11", L38, 0) -> 0 | AN38: =IF(P38="사용자항목12", L38, 0) -> 0 | AO38: =IF(P38="사용자항목13", L38, 0) -> 0 | AP38: =IF(P38="사용자항목14", L38, 0) -> 0 | AQ38: =IF(P38="사용자항목15", L38, 0) -> 0 | AR38: =IF(P38="사용자항목16", L38, 0) -> 0 | AS38: =IF(P38="사용자항목17", L38, 0) -> 0 | AT38: =IF(P38="사용자항목18", L38, 0) -> 0 | AU38: =IF(P38="사용자항목19", L38, 0) -> 0
A48: 합 계 | F48: =ROUNDDOWN(SUMIF(Q28:Q47, "1", F28:F47), 0) -> 0 | H48: =ROUNDDOWN(SUMIF(Q28:Q47, "1", H28:H47), 0) -> 0 | J48: =ROUNDDOWN(SUMIF(Q28:Q47, "1", J28:J47), 0) -> 0 | L48: =F48+H48+J48 -> 0 | R48: =ROUNDDOWN(SUM(R28:R38), 0) -> 0 | S48: =ROUNDDOWN(SUM(S28:S38), 0) -> 0 | T48: =ROUNDDOWN(SUM(T28:T38), 0) -> 0 | U48: =ROUNDDOWN(SUM(U28:U38), 0) -> 0 | V48: =ROUNDDOWN(SUM(V28:V38), 0) -> 0 | W48: =ROUNDDOWN(SUM(W28:W38), 0) -> 0 | X48: =ROUNDDOWN(SUM(X28:X38), 0) -> 0 | Y48: =ROUNDDOWN(SUM(Y28:Y38), 0) -> 0 | ... AY48: =ROUNDDOWN(SUM(AY28:AY38), 0) -> 0
A49: 1. 건축공사 > 3. 철거공사
A50: 목재창호철거 | C50: M2 | D50: 20.9 | M50: 일위 16호 | O50: ="" | P50: 기계경비 | Q50: 1 | R50: =IF(P50="기계경비", J50, 0) -> 0 | S50: =IF(P50="운반비", L50, 0) -> 0 | T50: =IF(P50="작업부산물", F50, 0) -> 0 | U50: =IF(P50="관급", F50, 0) -> 0 | V50: =IF(P50="외주비", J50, 0) -> 0 | W50: =IF(P50="장비비", J50, 0) -> 0 | X50: =IF(P50="폐기물처리비", L50, 0) -> 0 | Y50: =IF(P50="가설비", J50, 0) -> 0 | Z50: =IF(P50="잡비제외분", F50, 0) -> 0 | AA50: =IF(P50="사급자재대", L50, 0) -> 0 | AB50: =IF(P50="관급자재대", L50, 0) -> 0 | AC50: =IF(P50="관급자관급", L50, 0) -> 0 | AD50: =IF(P50="품질시험비", L50, 0) -> 0 | AE50: =IF(P50="수도광열비", L50, 0) -> 0 | AF50: =IF(P50="공기중석면농도측정비", L50, 0) -> 0 | AG50: =IF(P50="사용자항목5", L50, 0) -> 0 | AH50: =IF(P50="사용자항목6", L50, 0) -> 0 | AI50: =IF(P50="사용자항목7", L50, 0) -> 0 | AJ50: =IF(P50="관급자재대2", L50, 0) -> 0 | AK50: =IF(P50="작업부산물", L50, 0) -> 0 | AL50: =IF(P50="해체계획비및검토비", L50, 0) -> 0 | AM50: =IF(P50="사용자항목11", L50, 0) -> 0 | AN50: =IF(P50="사용자항목12", L50, 0) -> 0 | AO50: =IF(P50="사용자항목13", L50, 0) -> 0 | AP50: =IF(P50="사용자항목14", L50, 0) -> 0 | AQ50: =IF(P50="사용자항목15", L50, 0) -> 0 | AR50: =IF(P50="사용자항목16", L50, 0) -> 0 | AS50: =IF(P50="사용자항목17", L50, 0) -> 0 | AT50: =IF(P50="사용자항목18", L50, 0) -> 0 | AU50: =IF(P50="사용자항목19", L50, 0) -> 0
A51: 프라스틱 창 철거 | C51: M2 | D51: 1.8 | M51: 일위 17호 | O51: ="" | P51: 기계경비 | Q51: 1 | R51: =IF(P51="기계경비", J51, 0) -> 0 | S51: =IF(P51="운반비", L51, 0) -> 0 | T51: =IF(P51="작업부산물", F51, 0) -> 0 | U51: =IF(P51="관급", F51, 0) -> 0 | V51: =IF(P51="외주비", J51, 0) -> 0 | W51: =IF(P51="장비비", J51, 0) -> 0 | X51: =IF(P51="폐기물처리비", L51, 0) -> 0 | Y51: =IF(P51="가설비", J51, 0) -> 0 | Z51: =IF(P51="잡비제외분", F51, 0) -> 0 | AA51: =IF(P51="사급자재대", L51, 0) -> 0 | AB51: =IF(P51="관급자재대", L51, 0) -> 0 | AC51: =IF(P51="관급자관급", L51, 0) -> 0 | AD51: =IF(P51="품질시험비", L51, 0) -> 0 | AE51: =IF(P51="수도광열비", L51, 0) -> 0 | AF51: =IF(P51="공기중석면농도측정비", L51, 0) -> 0 | AG51: =IF(P51="사용자항목5", L51, 0) -> 0 | AH51: =IF(P51="사용자항목6", L51, 0) -> 0 | AI51: =IF(P51="사용자항목7", L51, 0) -> 0 | AJ51: =IF(P51="관급자재대2", L51, 0) -> 0 | AK51: =IF(P51="작업부산물", L51, 0) -> 0 | AL51: =IF(P51="해체계획비및검토비", L51, 0) -> 0 | AM51: =IF(P51="사용자항목11", L51, 0) -> 0 | AN51: =IF(P51="사용자항목12", L51, 0) -> 0 | AO51: =IF(P51="사용자항목13", L51, 0) -> 0 | AP51: =IF(P51="사용자항목14", L51, 0) -> 0 | AQ51: =IF(P51="사용자항목15", L51, 0) -> 0 | AR51: =IF(P51="사용자항목16", L51, 0) -> 0 | AS51: =IF(P51="사용자항목17", L51, 0) -> 0 | AT51: =IF(P51="사용자항목18", L51, 0) -> 0 | AU51: =IF(P51="사용자항목19", L51, 0) -> 0
A52: 콘크리트 절단(Wheel Saw) | B52: t=300mm이하 | C52: m | D52: 17.3 | M52: 일위 18호 | O52: ="" | P52: 기계경비 | Q52: 1 | R52: =IF(P52="기계경비", J52, 0) -> 0 | S52: =IF(P52="운반비", L52, 0) -> 0 | T52: =IF(P52="작업부산물", F52, 0) -> 0 | U52: =IF(P52="관급", F52, 0) -> 0 | V52: =IF(P52="외주비", J52, 0) -> 0 | W52: =IF(P52="장비비", J52, 0) -> 0 | X52: =IF(P52="폐기물처리비", L52, 0) -> 0 | Y52: =IF(P52="가설비", J52, 0) -> 0 | Z52: =IF(P52="잡비제외분", F52, 0) -> 0 | AA52: =IF(P52="사급자재대", L52, 0) -> 0 | AB52: =IF(P52="관급자재대", L52, 0) -> 0 | AC52: =IF(P52="관급자관급", L52, 0) -> 0 | AD52: =IF(P52="품질시험비", L52, 0) -> 0 | AE52: =IF(P52="수도광열비", L52, 0) -> 0 | AF52: =IF(P52="공기중석면농도측정비", L52, 0) -> 0 | AG52: =IF(P52="사용자항목5", L52, 0) -> 0 | AH52: =IF(P52="사용자항목6", L52, 0) -> 0 | AI52: =IF(P52="사용자항목7", L52, 0) -> 0 | AJ52: =IF(P52="관급자재대2", L52, 0) -> 0 | AK52: =IF(P52="작업부산물", L52, 0) -> 0 | AL52: =IF(P52="해체계획비및검토비", L52, 0) -> 0 | AM52: =IF(P52="사용자항목11", L52, 0) -> 0 | AN52: =IF(P52="사용자항목12", L52, 0) -> 0 | AO52: =IF(P52="사용자항목13", L52, 0) -> 0 | AP52: =IF(P52="사용자항목14", L52, 0) -> 0 | AQ52: =IF(P52="사용자항목15", L52, 0) -> 0 | AR52: =IF(P52="사용자항목16", L52, 0) -> 0 | AS52: =IF(P52="사용자항목17", L52, 0) -> 0 | AT52: =IF(P52="사용자항목18", L52, 0) -> 0 | AU52: =IF(P52="사용자항목19", L52, 0) -> 0 | AY52: 시장시공가격
A53: 콘크리트구조물 헐기(소형장비) | B53: 소형브레이커(전기식), 철근, 2.3m3/일당 | C53: M3 | D53: 0.3 | M53: 일위 19호 | O53: ="" | P53: 기계경비 | Q53: 1 | R53: =IF(P53="기계경비", J53, 0) -> 0 | S53: =IF(P53="운반비", L53, 0) -> 0 | T53: =IF(P53="작업부산물", F53, 0) -> 0 | U53: =IF(P53="관급", F53, 0) -> 0 | V53: =IF(P53="외주비", J53, 0) -> 0 | W53: =IF(P53="장비비", J53, 0) -> 0 | X53: =IF(P53="폐기물처리비", L53, 0) -> 0 | Y53: =IF(P53="가설비", J53, 0) -> 0 | Z53: =IF(P53="잡비제외분", F53, 0) -> 0 | AA53: =IF(P53="사급자재대", L53, 0) -> 0 | AB53: =IF(P53="관급자재대", L53, 0) -> 0 | AC53: =IF(P53="관급자관급", L53, 0) -> 0 | AD53: =IF(P53="품질시험비", L53, 0) -> 0 | AE53: =IF(P53="수도광열비", L53, 0) -> 0 | AF53: =IF(P53="공기중석면농도측정비", L53, 0) -> 0 | AG53: =IF(P53="사용자항목5", L53, 0) -> 0 | AH53: =IF(P53="사용자항목6", L53, 0) -> 0 | AI53: =IF(P53="사용자항목7", L53, 0) -> 0 | AJ53: =IF(P53="관급자재대2", L53, 0) -> 0 | AK53: =IF(P53="작업부산물", L53, 0) -> 0 | AL53: =IF(P53="해체계획비및검토비", L53, 0) -> 0 | AM53: =IF(P53="사용자항목11", L53, 0) -> 0 | AN53: =IF(P53="사용자항목12", L53, 0) -> 0 | AO53: =IF(P53="사용자항목13", L53, 0) -> 0 | AP53: =IF(P53="사용자항목14", L53, 0) -> 0 | AQ53: =IF(P53="사용자항목15", L53, 0) -> 0 | AR53: =IF(P53="사용자항목16", L53, 0) -> 0 | AS53: =IF(P53="사용자항목17", L53, 0) -> 0 | AT53: =IF(P53="사용자항목18", L53, 0) -> 0 | AU53: =IF(P53="사용자항목19", L53, 0) -> 0
A54: 벽돌벽 절단 | B54: W6∼12mm | C54: M | D54: 40 | M54: 일위 20호 | O54: ="" | P54: 기계경비 | Q54: 1 | R54: =IF(P54="기계경비", J54, 0) -> 0 | S54: =IF(P54="운반비", L54, 0) -> 0 | T54: =IF(P54="작업부산물", F54, 0) -> 0 | U54: =IF(P54="관급", F54, 0) -> 0 | V54: =IF(P54="외주비", J54, 0) -> 0 | W54: =IF(P54="장비비", J54, 0) -> 0 | X54: =IF(P54="폐기물처리비", L54, 0) -> 0 | Y54: =IF(P54="가설비", J54, 0) -> 0 | Z54: =IF(P54="잡비제외분", F54, 0) -> 0 | AA54: =IF(P54="사급자재대", L54, 0) -> 0 | AB54: =IF(P54="관급자재대", L54, 0) -> 0 | AC54: =IF(P54="관급자관급", L54, 0) -> 0 | AD54: =IF(P54="품질시험비", L54, 0) -> 0 | AE54: =IF(P54="수도광열비", L54, 0) -> 0 | AF54: =IF(P54="공기중석면농도측정비", L54, 0) -> 0 | AG54: =IF(P54="사용자항목5", L54, 0) -> 0 | AH54: =IF(P54="사용자항목6", L54, 0) -> 0 | AI54: =IF(P54="사용자항목7", L54, 0) -> 0 | AJ54: =IF(P54="관급자재대2", L54, 0) -> 0 | AK54: =IF(P54="작업부산물", L54, 0) -> 0 | AL54: =IF(P54="해체계획비및검토비", L54, 0) -> 0 | AM54: =IF(P54="사용자항목11", L54, 0) -> 0 | AN54: =IF(P54="사용자항목12", L54, 0) -> 0 | AO54: =IF(P54="사용자항목13", L54, 0) -> 0 | AP54: =IF(P54="사용자항목14", L54, 0) -> 0 | AQ54: =IF(P54="사용자항목15", L54, 0) -> 0 | AR54: =IF(P54="사용자항목16", L54, 0) -> 0 | AS54: =IF(P54="사용자항목17", L54, 0) -> 0 | AT54: =IF(P54="사용자항목18", L54, 0) -> 0 | AU54: =IF(P54="사용자항목19", L54, 0) -> 0
A55: 조적벽 해체 | B55: H=3.6m 이하 | C55: M3 | D55: 5.3 | M55: 일위 21호 | O55: ="" | P55: 기계경비 | Q55: 1 | R55: =IF(P55="기계경비", J55, 0) -> 0 | S55: =IF(P55="운반비", L55, 0) -> 0 | T55: =IF(P55="작업부산물", F55, 0) -> 0 | U55: =IF(P55="관급", F55, 0) -> 0 | V55: =IF(P55="외주비", J55, 0) -> 0 | W55: =IF(P55="장비비", J55, 0) -> 0 | X55: =IF(P55="폐기물처리비", L55, 0) -> 0 | Y55: =IF(P55="가설비", J55, 0) -> 0 | Z55: =IF(P55="잡비제외분", F55, 0) -> 0 | AA55: =IF(P55="사급자재대", L55, 0) -> 0 | AB55: =IF(P55="관급자재대", L55, 0) -> 0 | AC55: =IF(P55="관급자관급", L55, 0) -> 0 | AD55: =IF(P55="품질시험비", L55, 0) -> 0 | AE55: =IF(P55="수도광열비", L55, 0) -> 0 | AF55: =IF(P55="공기중석면농도측정비", L55, 0) -> 0 | AG55: =IF(P55="사용자항목5", L55, 0) -> 0 | AH55: =IF(P55="사용자항목6", L55, 0) -> 0 | AI55: =IF(P55="사용자항목7", L55, 0) -> 0 | AJ55: =IF(P55="관급자재대2", L55, 0) -> 0 | AK55: =IF(P55="작업부산물", L55, 0) -> 0 | AL55: =IF(P55="해체계획비및검토비", L55, 0) -> 0 | AM55: =IF(P55="사용자항목11", L55, 0) -> 0 | AN55: =IF(P55="사용자항목12", L55, 0) -> 0 | AO55: =IF(P55="사용자항목13", L55, 0) -> 0 | AP55: =IF(P55="사용자항목14", L55, 0) -> 0 | AQ55: =IF(P55="사용자항목15", L55, 0) -> 0 | AR55: =IF(P55="사용자항목16", L55, 0) -> 0 | AS55: =IF(P55="사용자항목17", L55, 0) -> 0 | AT55: =IF(P55="사용자항목18", L55, 0) -> 0 | AU55: =IF(P55="사용자항목19", L55, 0) -> 0
A56: 화강석 철거 | C56: M2 | D56: 2.9 | M56: 일위 22호 | O56: ="" | P56: 기계경비 | Q56: 1 | R56: =IF(P56="기계경비", J56, 0) -> 0 | S56: =IF(P56="운반비", L56, 0) -> 0 | T56: =IF(P56="작업부산물", F56, 0) -> 0 | U56: =IF(P56="관급", F56, 0) -> 0 | V56: =IF(P56="외주비", J56, 0) -> 0 | W56: =IF(P56="장비비", J56, 0) -> 0 | X56: =IF(P56="폐기물처리비", L56, 0) -> 0 | Y56: =IF(P56="가설비", J56, 0) -> 0 | Z56: =IF(P56="잡비제외분", F56, 0) -> 0 | AA56: =IF(P56="사급자재대", L56, 0) -> 0 | AB56: =IF(P56="관급자재대", L56, 0) -> 0 | AC56: =IF(P56="관급자관급", L56, 0) -> 0 | AD56: =IF(P56="품질시험비", L56, 0) -> 0 | AE56: =IF(P56="수도광열비", L56, 0) -> 0 | AF56: =IF(P56="공기중석면농도측정비", L56, 0) -> 0 | AG56: =IF(P56="사용자항목5", L56, 0) -> 0 | AH56: =IF(P56="사용자항목6", L56, 0) -> 0 | AI56: =IF(P56="사용자항목7", L56, 0) -> 0 | AJ56: =IF(P56="관급자재대2", L56, 0) -> 0 | AK56: =IF(P56="작업부산물", L56, 0) -> 0 | AL56: =IF(P56="해체계획비및검토비", L56, 0) -> 0 | AM56: =IF(P56="사용자항목11", L56, 0) -> 0 | AN56: =IF(P56="사용자항목12", L56, 0) -> 0 | AO56: =IF(P56="사용자항목13", L56, 0) -> 0 | AP56: =IF(P56="사용자항목14", L56, 0) -> 0 | AQ56: =IF(P56="사용자항목15", L56, 0) -> 0 | AR56: =IF(P56="사용자항목16", L56, 0) -> 0 | AS56: =IF(P56="사용자항목17", L56, 0) -> 0 | AT56: =IF(P56="사용자항목18", L56, 0) -> 0 | AU56: =IF(P56="사용자항목19", L56, 0) -> 0
A57: 경량천장철골틀 해체 | C57: M2 | D57: 186.4 | M57: 일위 23호 | O57: ="" | P57: 기계경비 | Q57: 1 | R57: =IF(P57="기계경비", J57, 0) -> 0 | S57: =IF(P57="운반비", L57, 0) -> 0 | T57: =IF(P57="작업부산물", F57, 0) -> 0 | U57: =IF(P57="관급", F57, 0) -> 0 | V57: =IF(P57="외주비", J57, 0) -> 0 | W57: =IF(P57="장비비", J57, 0) -> 0 | X57: =IF(P57="폐기물처리비", L57, 0) -> 0 | Y57: =IF(P57="가설비", J57, 0) -> 0 | Z57: =IF(P57="잡비제외분", F57, 0) -> 0 | AA57: =IF(P57="사급자재대", L57, 0) -> 0 | AB57: =IF(P57="관급자재대", L57, 0) -> 0 | AC57: =IF(P57="관급자관급", L57, 0) -> 0 | AD57: =IF(P57="품질시험비", L57, 0) -> 0 | AE57: =IF(P57="수도광열비", L57, 0) -> 0 | AF57: =IF(P57="공기중석면농도측정비", L57, 0) -> 0 | AG57: =IF(P57="사용자항목5", L57, 0) -> 0 | AH57: =IF(P57="사용자항목6", L57, 0) -> 0 | AI57: =IF(P57="사용자항목7", L57, 0) -> 0 | AJ57: =IF(P57="관급자재대2", L57, 0) -> 0 | AK57: =IF(P57="작업부산물", L57, 0) -> 0 | AL57: =IF(P57="해체계획비및검토비", L57, 0) -> 0 | AM57: =IF(P57="사용자항목11", L57, 0) -> 0 | AN57: =IF(P57="사용자항목12", L57, 0) -> 0 | AO57: =IF(P57="사용자항목13", L57, 0) -> 0 | AP57: =IF(P57="사용자항목14", L57, 0) -> 0 | AQ57: =IF(P57="사용자항목15", L57, 0) -> 0 | AR57: =IF(P57="사용자항목16", L57, 0) -> 0 | AS57: =IF(P57="사용자항목17", L57, 0) -> 0 | AT57: =IF(P57="사용자항목18", L57, 0) -> 0 | AU57: =IF(P57="사용자항목19", L57, 0) -> 0
A58: 흡음텍스 해체 | C58: M2 | D58: 186.4 | M58: 일위 24호 | O58: ="" | P58: 기계경비 | Q58: 1 | R58: =IF(P58="기계경비", J58, 0) -> 0 | S58: =IF(P58="운반비", L58, 0) -> 0 | T58: =IF(P58="작업부산물", F58, 0) -> 0 | U58: =IF(P58="관급", F58, 0) -> 0 | V58: =IF(P58="외주비", J58, 0) -> 0 | W58: =IF(P58="장비비", J58, 0) -> 0 | X58: =IF(P58="폐기물처리비", L58, 0) -> 0 | Y58: =IF(P58="가설비", J58, 0) -> 0 | Z58: =IF(P58="잡비제외분", F58, 0) -> 0 | AA58: =IF(P58="사급자재대", L58, 0) -> 0 | AB58: =IF(P58="관급자재대", L58, 0) -> 0 | AC58: =IF(P58="관급자관급", L58, 0) -> 0 | AD58: =IF(P58="품질시험비", L58, 0) -> 0 | AE58: =IF(P58="수도광열비", L58, 0) -> 0 | AF58: =IF(P58="공기중석면농도측정비", L58, 0) -> 0 | AG58: =IF(P58="사용자항목5", L58, 0) -> 0 | AH58: =IF(P58="사용자항목6", L58, 0) -> 0 | AI58: =IF(P58="사용자항목7", L58, 0) -> 0 | AJ58: =IF(P58="관급자재대2", L58, 0) -> 0 | AK58: =IF(P58="작업부산물", L58, 0) -> 0 | AL58: =IF(P58="해체계획비및검토비", L58, 0) -> 0 | AM58: =IF(P58="사용자항목11", L58, 0) -> 0 | AN58: =IF(P58="사용자항목12", L58, 0) -> 0 | AO58: =IF(P58="사용자항목13", L58, 0) -> 0 | AP58: =IF(P58="사용자항목14", L58, 0) -> 0 | AQ58: =IF(P58="사용자항목15", L58, 0) -> 0 | AR58: =IF(P58="사용자항목16", L58, 0) -> 0 | AS58: =IF(P58="사용자항목17", L58, 0) -> 0 | AT58: =IF(P58="사용자항목18", L58, 0) -> 0 | AU58: =IF(P58="사용자항목19", L58, 0) -> 0
A59: 칸막이벽 절단 | C59: M | D59: 20 | M59: 일위 25호 | O59: ="" | P59: 기계경비 | Q59: 1 | R59: =IF(P59="기계경비", J59, 0) -> 0 | S59: =IF(P59="운반비", L59, 0) -> 0 | T59: =IF(P59="작업부산물", F59, 0) -> 0 | U59: =IF(P59="관급", F59, 0) -> 0 | V59: =IF(P59="외주비", J59, 0) -> 0 | W59: =IF(P59="장비비", J59, 0) -> 0 | X59: =IF(P59="폐기물처리비", L59, 0) -> 0 | Y59: =IF(P59="가설비", J59, 0) -> 0 | Z59: =IF(P59="잡비제외분", F59, 0) -> 0 | AA59: =IF(P59="사급자재대", L59, 0) -> 0 | AB59: =IF(P59="관급자재대", L59, 0) -> 0 | AC59: =IF(P59="관급자관급", L59, 0) -> 0 | AD59: =IF(P59="품질시험비", L59, 0) -> 0 | AE59: =IF(P59="수도광열비", L59, 0) -> 0 | AF59: =IF(P59="공기중석면농도측정비", L59, 0) -> 0 | AG59: =IF(P59="사용자항목5", L59, 0) -> 0 | AH59: =IF(P59="사용자항목6", L59, 0) -> 0 | AI59: =IF(P59="사용자항목7", L59, 0) -> 0 | AJ59: =IF(P59="관급자재대2", L59, 0) -> 0 | AK59: =IF(P59="작업부산물", L59, 0) -> 0 | AL59: =IF(P59="해체계획비및검토비", L59, 0) -> 0 | AM59: =IF(P59="사용자항목11", L59, 0) -> 0 | AN59: =IF(P59="사용자항목12", L59, 0) -> 0 | AO59: =IF(P59="사용자항목13", L59, 0) -> 0 | AP59: =IF(P59="사용자항목14", L59, 0) -> 0 | AQ59: =IF(P59="사용자항목15", L59, 0) -> 0 | AR59: =IF(P59="사용자항목16", L59, 0) -> 0 | AS59: =IF(P59="사용자항목17", L59, 0) -> 0 | AT59: =IF(P59="사용자항목18", L59, 0) -> 0 | AU59: =IF(P59="사용자항목19", L59, 0) -> 0
A60: 샌드위치판넬 철거 | C60: M2 | D60: 21.6 | M60: 일위 26호 | O60: ="" | P60: 기계경비 | Q60: 1 | R60: =IF(P60="기계경비", J60, 0) -> 0 | S60: =IF(P60="운반비", L60, 0) -> 0 | T60: =IF(P60="작업부산물", F60, 0) -> 0 | U60: =IF(P60="관급", F60, 0) -> 0 | V60: =IF(P60="외주비", J60, 0) -> 0 | W60: =IF(P60="장비비", J60, 0) -> 0 | X60: =IF(P60="폐기물처리비", L60, 0) -> 0 | Y60: =IF(P60="가설비", J60, 0) -> 0 | Z60: =IF(P60="잡비제외분", F60, 0) -> 0 | AA60: =IF(P60="사급자재대", L60, 0) -> 0 | AB60: =IF(P60="관급자재대", L60, 0) -> 0 | AC60: =IF(P60="관급자관급", L60, 0) -> 0 | AD60: =IF(P60="품질시험비", L60, 0) -> 0 | AE60: =IF(P60="수도광열비", L60, 0) -> 0 | AF60: =IF(P60="공기중석면농도측정비", L60, 0) -> 0 | AG60: =IF(P60="사용자항목5", L60, 0) -> 0 | AH60: =IF(P60="사용자항목6", L60, 0) -> 0 | AI60: =IF(P60="사용자항목7", L60, 0) -> 0 | AJ60: =IF(P60="관급자재대2", L60, 0) -> 0 | AK60: =IF(P60="작업부산물", L60, 0) -> 0 | AL60: =IF(P60="해체계획비및검토비", L60, 0) -> 0 | AM60: =IF(P60="사용자항목11", L60, 0) -> 0 | AN60: =IF(P60="사용자항목12", L60, 0) -> 0 | AO60: =IF(P60="사용자항목13", L60, 0) -> 0 | AP60: =IF(P60="사용자항목14", L60, 0) -> 0 | AQ60: =IF(P60="사용자항목15", L60, 0) -> 0 | AR60: =IF(P60="사용자항목16", L60, 0) -> 0 | AS60: =IF(P60="사용자항목17", L60, 0) -> 0 | AT60: =IF(P60="사용자항목18", L60, 0) -> 0 | AU60: =IF(P60="사용자항목19", L60, 0) -> 0
A61: 샌드위치판넬 강판/단열재분리 | C61: M2 | D61: 21.6 | M61: 일위 27호 | O61: ="" | P61: 기계경비 | Q61: 1 | R61: =IF(P61="기계경비", J61, 0) -> 0 | S61: =IF(P61="운반비", L61, 0) -> 0 | T61: =IF(P61="작업부산물", F61, 0) -> 0 | U61: =IF(P61="관급", F61, 0) -> 0 | V61: =IF(P61="외주비", J61, 0) -> 0 | W61: =IF(P61="장비비", J61, 0) -> 0 | X61: =IF(P61="폐기물처리비", L61, 0) -> 0 | Y61: =IF(P61="가설비", J61, 0) -> 0 | Z61: =IF(P61="잡비제외분", F61, 0) -> 0 | AA61: =IF(P61="사급자재대", L61, 0) -> 0 | AB61: =IF(P61="관급자재대", L61, 0) -> 0 | AC61: =IF(P61="관급자관급", L61, 0) -> 0 | AD61: =IF(P61="품질시험비", L61, 0) -> 0 | AE61: =IF(P61="수도광열비", L61, 0) -> 0 | AF61: =IF(P61="공기중석면농도측정비", L61, 0) -> 0 | AG61: =IF(P61="사용자항목5", L61, 0) -> 0 | AH61: =IF(P61="사용자항목6", L61, 0) -> 0 | AI61: =IF(P61="사용자항목7", L61, 0) -> 0 | AJ61: =IF(P61="관급자재대2", L61, 0) -> 0 | AK61: =IF(P61="작업부산물", L61, 0) -> 0 | AL61: =IF(P61="해체계획비및검토비", L61, 0) -> 0 | AM61: =IF(P61="사용자항목11", L61, 0) -> 0 | AN61: =IF(P61="사용자항목12", L61, 0) -> 0 | AO61: =IF(P61="사용자항목13", L61, 0) -> 0 | AP61: =IF(P61="사용자항목14", L61, 0) -> 0 | AQ61: =IF(P61="사용자항목15", L61, 0) -> 0 | AR61: =IF(P61="사용자항목16", L61, 0) -> 0 | AS61: =IF(P61="사용자항목17", L61, 0) -> 0 | AT61: =IF(P61="사용자항목18", L61, 0) -> 0 | AU61: =IF(P61="사용자항목19", L61, 0) -> 0
A62: 건설폐재류 상차비 | C62: TON | D62: 9.427 | O62: ="03" -> 03 | P62: 기계경비 | Q62: 1 | R62: =IF(P62="기계경비", J62, 0) -> 0 | S62: =IF(P62="운반비", L62, 0) -> 0 | T62: =IF(P62="작업부산물", F62, 0) -> 0 | U62: =IF(P62="관급", F62, 0) -> 0 | V62: =IF(P62="외주비", J62, 0) -> 0 | W62: =IF(P62="장비비", J62, 0) -> 0 | X62: =IF(P62="폐기물처리비", L62, 0) -> 0 | Y62: =IF(P62="가설비", J62, 0) -> 0 | Z62: =IF(P62="잡비제외분", F62, 0) -> 0 | AA62: =IF(P62="사급자재대", L62, 0) -> 0 | AB62: =IF(P62="관급자재대", L62, 0) -> 0 | AC62: =IF(P62="관급자관급", L62, 0) -> 0 | AD62: =IF(P62="품질시험비", L62, 0) -> 0 | AE62: =IF(P62="수도광열비", L62, 0) -> 0 | AF62: =IF(P62="공기중석면농도측정비", L62, 0) -> 0 | AG62: =IF(P62="사용자항목5", L62, 0) -> 0 | AH62: =IF(P62="사용자항목6", L62, 0) -> 0 | AI62: =IF(P62="사용자항목7", L62, 0) -> 0 | AJ62: =IF(P62="관급자재대2", L62, 0) -> 0 | AK62: =IF(P62="작업부산물", L62, 0) -> 0 | AL62: =IF(P62="해체계획비및검토비", L62, 0) -> 0 | AM62: =IF(P62="사용자항목11", L62, 0) -> 0 | AN62: =IF(P62="사용자항목12", L62, 0) -> 0 | AO62: =IF(P62="사용자항목13", L62, 0) -> 0 | AP62: =IF(P62="사용자항목14", L62, 0) -> 0 | AQ62: =IF(P62="사용자항목15", L62, 0) -> 0 | AR62: =IF(P62="사용자항목16", L62, 0) -> 0 | AS62: =IF(P62="사용자항목17", L62, 0) -> 0 | AT62: =IF(P62="사용자항목18", L62, 0) -> 0 | AU62: =IF(P62="사용자항목19", L62, 0) -> 0
A63: 혼합건설폐기물 상차비 | B63: (매립지반입대상 폐기물 포함) | C63: TON | D63: 2.507 | O63: ="03" -> 03 | P63: 기계경비 | Q63: 1 | R63: =IF(P63="기계경비", J63, 0) -> 0 | S63: =IF(P63="운반비", L63, 0) -> 0 | T63: =IF(P63="작업부산물", F63, 0) -> 0 | U63: =IF(P63="관급", F63, 0) -> 0 | V63: =IF(P63="외주비", J63, 0) -> 0 | W63: =IF(P63="장비비", J63, 0) -> 0 | X63: =IF(P63="폐기물처리비", L63, 0) -> 0 | Y63: =IF(P63="가설비", J63, 0) -> 0 | Z63: =IF(P63="잡비제외분", F63, 0) -> 0 | AA63: =IF(P63="사급자재대", L63, 0) -> 0 | AB63: =IF(P63="관급자재대", L63, 0) -> 0 | AC63: =IF(P63="관급자관급", L63, 0) -> 0 | AD63: =IF(P63="품질시험비", L63, 0) -> 0 | AE63: =IF(P63="수도광열비", L63, 0) -> 0 | AF63: =IF(P63="공기중석면농도측정비", L63, 0) -> 0 | AG63: =IF(P63="사용자항목5", L63, 0) -> 0 | AH63: =IF(P63="사용자항목6", L63, 0) -> 0 | AI63: =IF(P63="사용자항목7", L63, 0) -> 0 | AJ63: =IF(P63="관급자재대2", L63, 0) -> 0 | AK63: =IF(P63="작업부산물", L63, 0) -> 0 | AL63: =IF(P63="해체계획비및검토비", L63, 0) -> 0 | AM63: =IF(P63="사용자항목11", L63, 0) -> 0 | AN63: =IF(P63="사용자항목12", L63, 0) -> 0 | AO63: =IF(P63="사용자항목13", L63, 0) -> 0 | AP63: =IF(P63="사용자항목14", L63, 0) -> 0 | AQ63: =IF(P63="사용자항목15", L63, 0) -> 0 | AR63: =IF(P63="사용자항목16", L63, 0) -> 0 | AS63: =IF(P63="사용자항목17", L63, 0) -> 0 | AT63: =IF(P63="사용자항목18", L63, 0) -> 0 | AU63: =IF(P63="사용자항목19", L63, 0) -> 0
...

Sheet 내역서(기계)
A1: [ 전남고2026학년도AI융합형교육실구축(기계) ]
A2: 품 명 | B2: 규 격 | C2: 단위 | D2: 수량 | E2: 재 료 비 | G2: 노 무 비 | I2: 경 비 | K2: 합 계 | M2: 비 고 | N2: 품목코드 | O2: 변수 | P2: 설정 | Q2: 공종코드 | R2: 일위 | S2: 단산 | T2: 자재 | U2: 손료적용 | V2: 손료저장 | W2: 적용율 | X2: JUK1 | Y2: JUK2 | Z2: JUK3 | AA2: JUK4 | AB2: JUK5 | AC2: JUK6 | AD2: JUK7 | AE2: JUK8 | AF2: JUK9 | AG2: JUK10 | AH2: JUK11 | AI2: JUK12 | AJ2: JUK13 | AK2: JUK14 | AL2: JUK15 | AM2: JUK16 | AN2: JUK17 | AO2: JUK18 | AP2: JUK19 | AQ2: JUK20 | AR2: 자재구분 | AS2: 공종구분 | AT2: 공종레벨 | AU2: 공종+자재 | AV2: 고유번호
E3: 단 가 | F3: 금 액 | G3: 단 가 | H3: 금 액 | I3: 단 가 | J3: 금 액 | K3: 단 가 | L3: 금 액
A4: 1-1.장비 및 위생기구 설치공사 | Q4: 010101
A5: 전기온수기 | B5: 전기온수기, 15L, 스테인리스 | C5: 대 | D5: 1 | M5: 호표 1 | N5: 58F285FA0B08C6AAA7685AF9056716 | Q5: 010101 | R5: T | S5: F | T5: F | AU5: 01010158F285FA0B08C6AAA7685AF9056716 | AV5: 7
A6: 주방수전(대붙이) | B6: 주방수전, 싱글레버, 1등급 | C6: 개 | D6: 1 | M6: 호표 2 | N6: 58F285FA0B08C6AAA7685AF9053742 | Q6: 010101 | R6: T | S6: F | T6: F | AU6: 01010158F285FA0B08C6AAA7685AF9053742 | AV6: 8
Q7: 010101
Q8: 010101
Q9: 010101
Q10: 010101
Q11: 010101
Q12: 010101
Q13: 010101
Q14: 010101
Q15: 010101
Q16: 010101
Q17: 010101
Q18: 010101
... Q26: 010101
A27: [ 합 계 ] | F27: =SUMIF(Q5:Q26,"010101",F5:F26) -> 0 | H27: =SUMIF(Q5:Q26,"010101",H5:H26) -> 0 | J27: =SUMIF(Q5:Q26,"010101",J5:J26) -> 0 | L27: =SUMIF(Q5:Q26,"010101",L5:L26) -> 0 | N27: TOTAL
A28: 1-2.급수, 급탕배관 설치공사 | Q28: 010102
